Workbook
Name Base_de_datos_gráficos: 'Carga HH'!$A$4:$U$1048576
Name GRAFICAR_CCD: #REF!
Name GRAFICAR_JP: #REF!
Name GRAFICAR_PyC: 'Carga HH'!$A$4:$U$1048576

Sheet Instructivo
A1: INSTRUCTIVO
A2: 1. La hoja "Registro" es para anotar tareas actuales (vigentes) y terminadas de los empleados, en dicha hoja se deberán anotar los datos de las tareas como la fecha de inicio, plazo, tiempo estimado y estado, además de la persona encargada.
A3: 2. La hoja "Carga de HH" no se debe mover, aquí se distribuyen las horas de cada activdidad asignada a cada empleado según la fecha de incio, plazo y tiempo estimado de la activadad, con un horizonte máximo de 3 meses (12 semanas)
A4: 3. Por último, la hoja "Gráficos HH" es para visualizar de forma más fácil la distribución actual de la carga de trabajo, es por esto que se hicieron diversos gráficos, los cuales van acompañados de su respectiva tabla en caso de querer ver más en detalle los valores. NOTA: Los gráficos no se actualizan solos, se debe ir a la pestaña "Datos" y hacer click en "Actualizar todos"

Sheet Registro
A1: Emplado | B1: Tarea/Actividad | C1: Fecha de inicio | D1: Plazo (fecha) | E1: Tiempo necesario estimado (Horas) | F1: Status tarea
A2: Daniela Rojas | B2: Reclutamiento y selección | C2: 45841 | D2: 45847 | E2: 6 | F2: Vigente | Q2: Actividad | R2: Tiempo estimado (horas)
A3: Vicente Castro | B3: Inducción y bienvenida | C3: 45841 | D3: 45848 | E3: 2.5 | F3: Vigente | Q3: Reclutamiento y selección | R3: 6
A4: Fernanda Morales | B4: Administración de personal | C4: 45841 | D4: 45848 | E4: 3 | F4: Vigente | Q4: Inducción y bienvenida | R4: 2.5
A5: Matías Herrera | B5: Gestión de remuneraciones y beneficios | C5: 45841 | D5: 45856 | E5: 9 | F5: Vigente | Q5: Administración de personal | R5: 3
A6: Camila González | B6: Capacitación y desarrollo | C6: 45841 | D6: 45856 | E6: 3 | F6: Terminado | Q6: Gestión de remuneraciones y beneficios | R6: 9
A7: Felipe Ramírez | B7: Evaluación del desempeño | C7: 45841 | D7: 45849 | E7: 10 | F7: Vigente | Q7: Capacitación y desarrollo | R7: 3
A8: Javiera Soto | B8: Gestión del clima laboral | C8: 45841 | D8: 45849 | E8: 3.5 | F8: Vigente | Q8: Evaluación del desempeño | R8: 10
A9: Daniela Rojas | B9: Gestión de conflictos y relaciones laborales | C9: 45841 | D9: 45852 | E9: 4 | F9: Vigente | Q9: Gestión del clima laboral | R9: 3.5
A10: Vicente Castro | B10: Gestión de salud y seguridad ocupacional | C10: 45841 | D10: 45852 | E10: 2.5 | F10: Vigente | Q10: Gestión de conflictos y relaciones laborales | R10: 4
A11: Fernanda Morales | B11: Cumplimiento legal y normativo | C11: 45841 | D11: 45847 | E11: 3 | F11: Vigente | Q11: Gestión de salud y seguridad ocupacional | R11: 2.5
A12: Camila González | B12: Reclutamiento y selección | C12: 45841 | D12: 45848 | E12: 6 | F12: Vigente | Q12: Cumplimiento legal y normativo | R12: 3
A13: Felipe Ramírez | B13: Inducción y bienvenida | C13: 45841 | D13: 45848 | E13: 2.5 | F13: Vigente | Q13: Comunicación interna | R13: 1.5
A14: Javiera Soto | B14: Administración de personal | C14: 45841 | D14: 45849 | E14: 3 | F14: Vigente | Q14: Monitoreo y gestión de carga laboral | R14: 2.5
A15: Daniela Rojas | B15: Gestión de remuneraciones y beneficios | C15: 45841 | D15: 45849 | E15: 9 | F15: Vigente
A16: Vicente Castro | B16: Capacitación y desarrollo | C16: 45841 | D16: 45849 | E16: 3 | F16: Vigente
A17: Fernanda Morales | B17: Evaluación del desempeño | C17: 45841 | D17: 45852 | E17: 10 | F17: Vigente
A18: Daniela Rojas | B18: Reclutamiento y selección | C18: =C2+14 -> 45855 | D18: =D2+14 -> 45861 | E18: 6 | F18: Vigente
A19: Vicente Castro | B19: Inducción y bienvenida | C19: =C3+14 -> 45855 | D19: =D3+14 -> 45862 | E19: 2.5 | F19: Vigente
A20: Fernanda Morales | B20: Administración de personal | C20: =C4+14 -> 45855 | D20: =D4+14 -> 45862 | E20: 3 | F20: Vigente
A21: Matías Herrera | B21: Gestión de remuneraciones y beneficios | C21: =C5+14 -> 45855 | D21: =D5+14 -> 45870 | E21: 9 | F21: Vigente
A22: Camila González | B22: Capacitación y desarrollo | C22: =C6+14 -> 45855 | D22: =D6+14 -> 45870 | E22: 3 | F22: Vigente
A23: Felipe Ramírez | B23: Evaluación del desempeño | C23: =C7+14 -> 45855 | D23: =D7+14 -> 45863 | E23: 10 | F23: Vigente
A24: Javiera Soto | B24: Gestión del clima laboral | C24: =C8+14 -> 45855 | D24: =D8+14 -> 45863 | E24: 3.5 | F24: Vigente
A25: Daniela Rojas | B25: Gestión de conflictos y relaciones laborales | C25: =C9+14 -> 45855 | D25: =D9+14 -> 45866 | E25: 4 | F25: Vigente
A26: Vicente Castro | B26: Gestión de salud y seguridad ocupacional | C26: =C10+14 -> 45855 | D26: =D10+14 -> 45866 | E26: 2.5 | F26: Vigente
A27: Fernanda Morales | B27: Cumplimiento legal y normativo | C27: =C11+14 -> 45855 | D27: =D11+14 -> 45861 | E27: 3 | F27: Vigente
A28: Camila González | B28: Reclutamiento y selección | C28: =C12+14 -> 45855 | D28: =D12+14 -> 45862 | E28: 6 | F28: Vigente
A29: Felipe Ramírez | B29: Inducción y bienvenida | C29: =C13+14 -> 45855 | D29: =D13+14 -> 45862 | E29: 2.5 | F29: Vigente
... A33: Fernanda Morales | B33: Evaluación del desempeño | C33: =C17+14 -> 45855 | D33: =D17+14 -> 45866 | E33: 10 | F33: Vigente
A34: Daniela Rojas | B34: Gestión de remuneraciones y beneficios | C34: =C2+7 -> 45848 | D34: =C34+7 -> 45855 | E34: =VLOOKUP(B34,$Q$2:$R$14,2,FALSE) -> 9 | F34: Vigente
A35: Vicente Castro | B35: Administración de personal | C35: =C3+7 -> 45848 | D35: =C35+7 -> 45855 | E35: =VLOOKUP(B35,$Q$2:$R$14,2,FALSE) -> 3 | F35: Vigente
A36: Fernanda Morales | B36: Inducción y bienvenida | C36: =C4+7 -> 45848 | D36: =C36+7 -> 45855 | E36: =VLOOKUP(B36,$Q$2:$R$14,2,FALSE) -> 2.5 | F36: Vigente
A37: Matías Herrera | B37: Reclutamiento y selección | C37: =C5+7 -> 45848 | D37: =C37+7 -> 45855 | E37: =VLOOKUP(B37,$Q$2:$R$14,2,FALSE) -> 6 | F37: Vigente
A38: Camila González | B38: Cumplimiento legal y normativo | C38: =C6+7 -> 45848 | D38: =C38+7 -> 45855 | E38: =VLOOKUP(B38,$Q$2:$R$14,2,FALSE) -> 3 | F38: Vigente
A39: Felipe Ramírez | B39: Gestión de conflictos y relaciones laborales | C39: =C7+7 -> 45848 | D39: =C39+7 -> 45855 | E39: =VLOOKUP(B39,$Q$2:$R$14,2,FALSE) -> 4 | F39: Vigente
A40: Javiera Soto | B40: Capacitación y desarrollo | C40: =C8+7 -> 45848 | D40: =C40+7 -> 45855 | E40: =VLOOKUP(B40,$Q$2:$R$14,2,FALSE) -> 3 | F40: Vigente
A41: Daniela Rojas | B41: Gestión del clima laboral | C41: =C9+7 -> 45848 | D41: =C41+7 -> 45855 | E41: =VLOOKUP(B41,$Q$2:$R$14,2,FALSE) -> 3.5 | F41: Vigente
A42: Vicente Castro | B42: Inducción y bienvenida | C42: =C10+7 -> 45848 | D42: =C42+7 -> 45855 | E42: =VLOOKUP(B42,$Q$2:$R$14,2,FALSE) -> 2.5 | F42: Vigente
A43: Fernanda Morales | B43: Administración de personal | C43: =C11+7 -> 45848 | D43: =C43+7 -> 45855 | E43: =VLOOKUP(B43,$Q$2:$R$14,2,FALSE) -> 3 | F43: Vigente
...

Sheet BD
A1: Emplado | B1: Tarea/Actividad | C1: Fecha de inicio | D1: Plazo (fecha) | E1: Tiempo necesario estimado (Horas) | F1: Tiempo restante | G1: Días restantes | H1: Semanas restantes | I1: HH por día | J1: NUM SEM | K1: HH | L1: SEMANA2 | M1: LUNES a DOMINGO | O1: SEMANA | P1: LUNES
A2: Camila González | B2: Reclutamiento y selección | C2: 45841 | D2: 45848 | E2: 6 | F2: 3 | G2: 5 | H2: 1 | I2: 1 | J2: S-1 | K2: 0 | L2: =IFERROR(VLOOKUP(J2,$O$2:$P$13,2),"") -> 46167 | M2: =IFERROR(TEXT(L2,"dd/mm/yyyy")& " a " & (TEXT(L2+6,"dd/mm/yyyy")),"") -> 25/05/yyyy a 31/05/yyyy | O2: S-1 | P2: ='Carga HH'!J3 -> 46167
A3: Camila González | B3: Reclutamiento y selección | C3: 45841 | D3: 45848 | E3: 6 | F3: 3 | G3: 5 | H3: 1 | I3: 1 | J3: S-2 | K3: 4 | L3: =IFERROR(VLOOKUP(J3,$O$2:$P$13,2),"") -> 46174 | M3: =IFERROR(TEXT(L3,"dd/mm/yyyy")& " a " & (TEXT(L3+6,"dd/mm/yyyy")),"") -> 01/06/yyyy a 07/06/yyyy | O3: S-2 | P3: ='Carga HH'!K3 -> 46174
A4: Camila González | B4: Reclutamiento y selección | C4: 45841 | D4: 45848 | E4: 6 | F4: 3 | G4: 5 | H4: 1 | I4: 1 | J4: S-3 | K4: 0 | L4: =IFERROR(VLOOKUP(J4,$O$2:$P$13,2),"") -> 46181 | M4: =IFERROR(TEXT(L4,"dd/mm/yyyy")& " a " & (TEXT(L4+6,"dd/mm/yyyy")),"") -> 08/06/yyyy a 14/06/yyyy | O4: S-3 | P4: ='Carga HH'!L3 -> 46181
A5: Camila González | B5: Reclutamiento y selección | C5: 45841 | D5: 45848 | E5: 6 | F5: 3 | G5: 5 | H5: 1 | I5: 1 | J5: S-4 | K5: 0 | L5: =IFERROR(VLOOKUP(J5,$O$2:$P$13,2),"") -> 46188 | M5: =IFERROR(TEXT(L5,"dd/mm/yyyy")& " a " & (TEXT(L5+6,"dd/mm/yyyy")),"") -> 15/06/yyyy a 21/06/yyyy | O5: S-4 | P5: ='Carga HH'!M3 -> 46188
A6: Camila González | B6: Reclutamiento y selección | C6: 45841 | D6: 45848 | E6: 6 | F6: 3 | G6: 5 | H6: 1 | I6: 1 | J6: S-5 | K6: 0 | L6: =IFERROR(VLOOKUP(J6,$O$2:$P$13,2),"") -> 46195 | M6: =IFERROR(TEXT(L6,"dd/mm/yyyy")& " a " & (TEXT(L6+6,"dd/mm/yyyy")),"") -> 22/06/yyyy a 28/06/yyyy | O6: S-5 | P6: ='Carga HH'!N3 -> 46195
A7: Camila González | B7: Reclutamiento y selección | C7: 45841 | D7: 45848 | E7: 6 | F7: 3 | G7: 5 | H7: 1 | I7: 1 | J7: S-6 | K7: 0 | L7: =IFERROR(VLOOKUP(J7,$O$2:$P$13,2),"") -> 46202 | M7: =IFERROR(TEXT(L7,"dd/mm/yyyy")& " a " & (TEXT(L7+6,"dd/mm/yyyy")),"") -> 29/06/yyyy a 05/07/yyyy | O7: S-6 | P7: ='Carga HH'!O3 -> 46202
A8: Camila González | B8: Reclutamiento y selección | C8: 45841 | D8: 45848 | E8: 6 | F8: 3 | G8: 5 | H8: 1 | I8: 1 | J8: S-7 | K8: 0 | L8: =IFERROR(VLOOKUP(J8,$O$2:$P$13,2),"") -> 46209 | M8: =IFERROR(TEXT(L8,"dd/mm/yyyy")& " a " & (TEXT(L8+6,"dd/mm/yyyy")),"") -> 06/07/yyyy a 12/07/yyyy | O8: S-7 | P8: ='Carga HH'!P3 -> 46209
A9: Camila González | B9: Reclutamiento y selección | C9: 45841 | D9: 45848 | E9: 6 | F9: 3 | G9: 5 | H9: 1 | I9: 1 | J9: S-8 | K9: 0 | L9: =IFERROR(VLOOKUP(J9,$O$2:$P$13,2),"") -> 46216 | M9: =IFERROR(TEXT(L9,"dd/mm/yyyy")& " a " & (TEXT(L9+6,"dd/mm/yyyy")),"") -> 13/07/yyyy a 19/07/yyyy | O9: S-8 | P9: ='Carga HH'!Q3 -> 46216
A10: Camila González | B10: Reclutamiento y selección | C10: 45841 | D10: 45848 | E10: 6 | F10: 3 | G10: 5 | H10: 1 | I10: 1 | J10: S-9 | K10: 0 | L10: =IFERROR(VLOOKUP(J10,$O$2:$P$13,2),"") -> 46223 | M10: =IFERROR(TEXT(L10,"dd/mm/yyyy")& " a " & (TEXT(L10+6,"dd/mm/yyyy")),"") -> 20/07/yyyy a 26/07/yyyy | O10: S-9 | P10: ='Carga HH'!R3 -> 46223
A11: Camila González | B11: Reclutamiento y selección | C11: 45841 | D11: 45848 | E11: 6 | F11: 3 | G11: 5 | H11: 1 | I11: 1 | J11: S-10 | K11: 0 | L11: =IFERROR(VLOOKUP(J11,$O$2:$P$13,2),"") -> 46167 | M11: =IFERROR(TEXT(L11,"dd/mm/yyyy")& " a " & (TEXT(L11+6,"dd/mm/yyyy")),"") -> 25/05/yyyy a 31/05/yyyy | O11: S-10 | P11: ='Carga HH'!S3 -> 46230
A12: Camila González | B12: Reclutamiento y selección | C12: 45841 | D12: 45848 | E12: 6 | F12: 3 | G12: 5 | H12: 1 | I12: 1 | J12: S-11 | K12: 0 | L12: =IFERROR(VLOOKUP(J12,$O$2:$P$13,2),"") -> 46167 | M12: =IFERROR(TEXT(L12,"dd/mm/yyyy")& " a " & (TEXT(L12+6,"dd/mm/yyyy")),"") -> 25/05/yyyy a 31/05/yyyy | O12: S-11 | P12: ='Carga HH'!T3 -> 46237
A13: Camila González | B13: Reclutamiento y selección | C13: 45841 | D13: 45848 | E13: 6 | F13: 3 | G13: 5 | H13: 1 | I13: 1 | J13: S-12 | K13: 0 | L13: =IFERROR(VLOOKUP(J13,$O$2:$P$13,2),"") -> 46167 | M13: =IFERROR(TEXT(L13,"dd/mm/yyyy")& " a " & (TEXT(L13+6,"dd/mm/yyyy")),"") -> 25/05/yyyy a 31/05/yyyy | O13: S-12 | P13: ='Carga HH'!U3 -> 46244
A14: Camila González | B14: Capacitación y desarrollo | C14: 45855 | D14: 45870 | E14: 3 | F14: 3 | G14: 21 | H14: 4.2 | I14: 0.25 | J14: S-1 | K14: 0 | L14: =IFERROR(VLOOKUP(J14,$O$2:$P$13,2),"") -> 46167 | M14: =IFERROR(TEXT(L14,"dd/mm/yyyy")& " a " & (TEXT(L14+6,"dd/mm/yyyy")),"") -> 25/05/yyyy a 31/05/yyyy
A15: Camila González | B15: Capacitación y desarrollo | C15: 45855 | D15: 45870 | E15: 3 | F15: 3 | G15: 21 | H15: 4.2 | I15: 0.25 | J15: S-2 | K15: 0 | L15: =IFERROR(VLOOKUP(J15,$O$2:$P$13,2),"") -> 46174 | M15: =IFERROR(TEXT(L15,"dd/mm/yyyy")& " a " & (TEXT(L15+6,"dd/mm/yyyy")),"") -> 01/06/yyyy a 07/06/yyyy
A16: Camila González | B16: Capacitación y desarrollo | C16: 45855 | D16: 45870 | E16: 3 | F16: 3 | G16: 21 | H16: 4.2 | I16: 0.25 | J16: S-3 | K16: 0.5 | L16: =IFERROR(VLOOKUP(J16,$O$2:$P$13,2),"") -> 46181 | M16: =IFERROR(TEXT(L16,"dd/mm/yyyy")& " a " & (TEXT(L16+6,"dd/mm/yyyy")),"") -> 08/06/yyyy a 14/06/yyyy
A17: Camila González | B17: Capacitación y desarrollo | C17: 45855 | D17: 45870 | E17: 3 | F17: 3 | G17: 21 | H17: 4.2 | I17: 0.25 | J17: S-4 | K17: 1.25 | L17: =IFERROR(VLOOKUP(J17,$O$2:$P$13,2),"") -> 46188 | M17: =IFERROR(TEXT(L17,"dd/mm/yyyy")& " a " & (TEXT(L17+6,"dd/mm/yyyy")),"") -> 15/06/yyyy a 21/06/yyyy
A18: Camila González | B18: Capacitación y desarrollo | C18: 45855 | D18: 45870 | E18: 3 | F18: 3 | G18: 21 | H18: 4.2 | I18: 0.25 | J18: S-5 | K18: 1.25 | L18: =IFERROR(VLOOKUP(J18,$O$2:$P$13,2),"") -> 46195 | M18: =IFERROR(TEXT(L18,"dd/mm/yyyy")& " a " & (TEXT(L18+6,"dd/mm/yyyy")),"") -> 22/06/yyyy a 28/06/yyyy
A19: Camila González | B19: Capacitación y desarrollo | C19: 45855 | D19: 45870 | E19: 3 | F19: 3 | G19: 21 | H19: 4.2 | I19: 0.25 | J19: S-6 | K19: 0 | L19: =IFERROR(VLOOKUP(J19,$O$2:$P$13,2),"") -> 46202 | M19: =IFERROR(TEXT(L19,"dd/mm/yyyy")& " a " & (TEXT(L19+6,"dd/mm/yyyy")),"") -> 29/06/yyyy a 05/07/yyyy
A20: Camila González | B20: Capacitación y desarrollo | C20: 45855 | D20: 45870 | E20: 3 | F20: 3 | G20: 21 | H20: 4.2 | I20: 0.25 | J20: S-7 | K20: 0 | L20: =IFERROR(VLOOKUP(J20,$O$2:$P$13,2),"") -> 46209 | M20: =IFERROR(TEXT(L20,"dd/mm/yyyy")& " a " & (TEXT(L20+6,"dd/mm/yyyy")),"") -> 06/07/yyyy a 12/07/yyyy
A21: Camila González | B21: Capacitación y desarrollo | C21: 45855 | D21: 45870 | E21: 3 | F21: 3 | G21: 21 | H21: 4.2 | I21: 0.25 | J21: S-8 | K21: 0 | L21: =IFERROR(VLOOKUP(J21,$O$2:$P$13,2),"") -> 46216 | M21: =IFERROR(TEXT(L21,"dd/mm/yyyy")& " a " & (TEXT(L21+6,"dd/mm/yyyy")),"") -> 13/07/yyyy a 19/07/yyyy
A22: Camila González | B22: Capacitación y desarrollo | C22: 45855 | D22: 45870 | E22: 3 | F22: 3 | G22: 21 | H22: 4.2 | I22: 0.25 | J22: S-9 | K22: 0 | L22: =IFERROR(VLOOKUP(J22,$O$2:$P$13,2),"") -> 46223 | M22: =IFERROR(TEXT(L22,"dd/mm/yyyy")& " a " & (TEXT(L22+6,"dd/mm/yyyy")),"") -> 20/07/yyyy a 26/07/yyyy
A23: Camila González | B23: Capacitación y desarrollo | C23: 45855 | D23: 45870 | E23: 3 | F23: 3 | G23: 21 | H23: 4.2 | I23: 0.25 | J23: S-10 | K23: 0 | L23: =IFERROR(VLOOKUP(J23,$O$2:$P$13,2),"") -> 46167 | M23: =IFERROR(TEXT(L23,"dd/mm/yyyy")& " a " & (TEXT(L23+6,"dd/mm/yyyy")),"") -> 25/05/yyyy a 31/05/yyyy
A24: Camila González | B24: Capacitación y desarrollo | C24: 45855 | D24: 45870 | E24: 3 | F24: 3 | G24: 21 | H24: 4.2 | I24: 0.25 | J24: S-11 | K24: 0 | L24: =IFERROR(VLOOKUP(J24,$O$2:$P$13,2),"") -> 46167 | M24: =IFERROR(TEXT(L24,"dd/mm/yyyy")& " a " & (TEXT(L24+6,"dd/mm/yyyy")),"") -> 25/05/yyyy a 31/05/yyyy
A25: Camila González | B25: Capacitación y desarrollo | C25: 45855 | D25: 45870 | E25: 3 | F25: 3 | G25: 21 | H25: 4.2 | I25: 0.25 | J25: S-12 | K25: 0 | L25: =IFERROR(VLOOKUP(J25,$O$2:$P$13,2),"") -> 46167 | M25: =IFERROR(TEXT(L25,"dd/mm/yyyy")& " a " & (TEXT(L25+6,"dd/mm/yyyy")),"") -> 25/05/yyyy a 31/05/yyyy
... A1009: Vicente Castro | B1009: Administración de personal | C1009: 45862 | D1009: 45869 | E1009: 3 | F1009: 3 | G1009: 20 | H1009: 4 | I1009: 0.5 | J1009: S-12 | K1009: 0 | L1009: =IFERROR(VLOOKUP(J1009,$O$2:$P$13,2),"") -> 46167 | M1009: =IFERROR(TEXT(L1009,"dd/mm/yyyy")& " a " & (TEXT(L1009+6,"dd/mm/yyyy")),"") -> 25/05/yyyy a 31/05/yyyy

Sheet Carga HH
A3: FILTRO | F3: ARRASTRAR | J3: =TODAY()-MOD(TODAY()-2,7) -> 46167 | K3: =J3+7 -> 46174 | L3: =K3+7 -> 46181 | M3: =L3+7 -> 46188 | N3: =M3+7 -> 46195 | O3: =N3+7 -> 46202 | P3: =O3+7 -> 46209 | Q3: =P3+7 -> 46216 | R3: =Q3+7 -> 46223 | ... U3: =T3+7 -> 46244
A4: Emplado | B4: Tarea/Actividad | C4: Fecha de inicio | D4: Plazo (fecha) | E4: Tiempo necesario estimado (Horas) | F4: Tiempo restante | G4: Días restantes | H4: Semanas restantes | I4: HH por día | J4: S-1 | K4: S-2 | L4: S-3 | M4: S-4 | N4: S-5 | O4: S-6 | P4: S-7 | Q4: S-8 | R4: S-9 | S4: S-10 | T4: S-11 | U4: S-12
A5: {=_xlfn._xlws.SORT(_xlfn._xlws.FILTER(CHOOSE({1,2,3,4,5}, Registro!A2:A99986, Registro!B2:B99986,Registro!C2:C99986,Registro!D2:D99986, Registro!E2:E99986), Registro!F2:F99986="Vigente"), 1, TRUE)} -> Camila González | B5: Reclutamiento y selección | C5: 45841 | D5: 45848 | E5: 6 | F5: =IF(E5="","",E5-IF(TODAY()<C5,0,(TODAY()-C5)*I5)) -> -321 | G5: =IF(E5="","",NETWORKDAYS(TODAY(),D5)+1) -> -228 | H5: =IF(E5="","",G5/5) -> -45.6 | I5: =IF(E5="","",E5/((NETWORKDAYS(C5,D5)))) -> 1 | J5: =IF($A5="","", IF($C5>J$3+6,0,IF($D5>=J$3,$I5*5,0) -IF($D5>=J$3,IF(K$3>$D5,NETWORKDAYS($D5,K$3)-2,0)*$I5,0) -IF(AND($C5>=J$3,$C5<K$3),($C5-J$3)*$I5,0)) -IF(AND(TODAY()>=J$3,TODAY()<K$3),IF(TODAY()>$C5,NETWORKDAYS($C5,TODAY()-1)*$I5,0),0) ) -> -233 | K5: =IF($A5="","", IF($C5>K$3+6,0,IF($D5>=K$3,$I5*5,0) -IF($D5>=K$3,IF(L$3>$D5,NETWORKDAYS($D5,L$3)-2,0)*$I5,0) -IF(AND($C5>=K$3,$C5<L$3),($C5-K$3)*$I5,0)) -IF(AND(TODAY()>=K$3,TODAY()<L$3),IF(TODAY()>$C5,NETWORKDAYS($C5,TODAY()-1)*$I5,0),0) ) -> 0 | L5: =IF($A5="","", IF($C5>L$3+6,0,IF($D5>=L$3,$I5*5,0) -IF($D5>=L$3,IF(M$3>$D5,NETWORKDAYS($D5,M$3)-2,0)*$I5,0) -IF(AND($C5>=L$3,$C5<M$3),($C5-L$3)*$I5,0)) -IF(AND(TODAY()>=L$3,TODAY()<M$3),IF(TODAY()>$C5,NETWORKDAYS($C5,TODAY()-1)*$I5,0),0) ) -> 0 | M5: =IF($A5="","", IF($C5>M$3+6,0,IF($D5>=M$3,$I5*5,0) -IF($D5>=M$3,IF(N$3>$D5,NETWORKDAYS($D5,N$3)-2,0)*$I5,0) -IF(AND($C5>=M$3,$C5<N$3),($C5-M$3)*$I5,0)) -IF(AND(TODAY()>=M$3,TODAY()<N$3),IF(TODAY()>$C5,NETWORKDAYS($C5,TODAY()-1)*$I5,0),0) ) -> 0 | N5: =IF($A5="","", IF($C5>N$3+6,0,IF($D5>=N$3,$I5*5,0) -IF($D5>=N$3,IF(O$3>$D5,NETWORKDAYS($D5,O$3)-2,0)*$I5,0) -IF(AND($C5>=N$3,$C5<O$3),($C5-N$3)*$I5,0)) -IF(AND(TODAY()>=N$3,TODAY()<O$3),IF(TODAY()>$C5,NETWORKDAYS($C5,TODAY()-1)*$I5,0),0) ) -> 0 | O5: =IF($A5="","", IF($C5>O$3+6,0,IF($D5>=O$3,$I5*5,0) -IF($D5>=O$3,IF(P$3>$D5,NETWORKDAYS($D5,P$3)-2,0)*$I5,0) -IF(AND($C5>=O$3,$C5<P$3),($C5-O$3)*$I5,0)) -IF(AND(TODAY()>=O$3,TODAY()<P$3),IF(TODAY()>$C5,NETWORKDAYS($C5,TODAY()-1)*$I5,0),0) ) -> 0 | P5: =IF($A5="","", IF($C5>P$3+6,0,IF($D5>=P$3,$I5*5,0) -IF($D5>=P$3,IF(Q$3>$D5,NETWORKDAYS($D5,Q$3)-2,0)*$I5,0) -IF(AND($C5>=P$3,$C5<Q$3),($C5-P$3)*$I5,0)) -IF(AND(TODAY()>=P$3,TODAY()<Q$3),IF(TODAY()>$C5,NETWORKDAYS($C5,TODAY()-1)*$I5,0),0) ) -> 0 | Q5: =IF($A5="","", IF($C5>Q$3+6,0,IF($D5>=Q$3,$I5*5,0) -IF($D5>=Q$3,IF(R$3>$D5,NETWORKDAYS($D5,R$3)-2,0)*$I5,0) -IF(AND($C5>=Q$3,$C5<R$3),($C5-Q$3)*$I5,0)) -IF(AND(TODAY()>=Q$3,TODAY()<R$3),IF(TODAY()>$C5,NETWORKDAYS($C5,TODAY()-1)*$I5,0),0) ) -> 0 | ... U5: =IF($A5="","", IF($C5>U$3+6,0,IF($D5>=U$3,$I5*5,0) -IF($D5>=U$3,IF(V$3>$D5,NETWORKDAYS($D5,V$3)-2,0)*$I5,0) -IF(AND($C5>=U$3,$C5<V$3),($C5-U$3)*$I5,0)) -IF(AND(TODAY()>=U$3,TODAY()<V$3),IF(TODAY()>$C5,NETWORKDAYS($C5,TODAY()-1)*$I5,0),0) ) -> 0 | W5: =SUM(J5:U5) -> -233 | X5: =W5=F5 -> FALSE
A6: Camila González | B6: Capacitación y desarrollo | C6: 45855 | D6: 45870 | E6: 3 | F6: =IF(E6="","",E6-IF(TODAY()<C6,0,(TODAY()-C6)*I6)) -> -75.25 | G6: =IF(E6="","",NETWORKDAYS(TODAY(),D6)+1) -> -212 | H6: =IF(E6="","",G6/5) -> -42.4 | I6: =IF(E6="","",E6/((NETWORKDAYS(C6,D6)))) -> 0.25 | J6: =IF($A6="","", IF($C6>J$3+6,0,IF($D6>=J$3,$I6*5,0) -IF($D6>=J$3,IF(K$3>$D6,NETWORKDAYS($D6,K$3)-2,0)*$I6,0) -IF(AND($C6>=J$3,$C6<K$3),($C6-J$3)*$I6,0)) -IF(AND(TODAY()>=J$3,TODAY()<K$3),IF(TODAY()>$C6,NETWORKDAYS($C6,TODAY()-1)*$I6,0),0) ) -> -55.75 | K6: =IF($A6="","", IF($C6>K$3+6,0,IF($D6>=K$3,$I6*5,0) -IF($D6>=K$3,IF(L$3>$D6,NETWORKDAYS($D6,L$3)-2,0)*$I6,0) -IF(AND($C6>=K$3,$C6<L$3),($C6-K$3)*$I6,0)) -IF(AND(TODAY()>=K$3,TODAY()<L$3),IF(TODAY()>$C6,NETWORKDAYS($C6,TODAY()-1)*$I6,0),0) ) -> 0 | L6: =IF($A6="","", IF($C6>L$3+6,0,IF($D6>=L$3,$I6*5,0) -IF($D6>=L$3,IF(M$3>$D6,NETWORKDAYS($D6,M$3)-2,0)*$I6,0) -IF(AND($C6>=L$3,$C6<M$3),($C6-L$3)*$I6,0)) -IF(AND(TODAY()>=L$3,TODAY()<M$3),IF(TODAY()>$C6,NETWORKDAYS($C6,TODAY()-1)*$I6,0),0) ) -> 0 | M6: =IF($A6="","", IF($C6>M$3+6,0,IF($D6>=M$3,$I6*5,0) -IF($D6>=M$3,IF(N$3>$D6,NETWORKDAYS($D6,N$3)-2,0)*$I6,0) -IF(AND($C6>=M$3,$C6<N$3),($C6-M$3)*$I6,0)) -IF(AND(TODAY()>=M$3,TODAY()<N$3),IF(TODAY()>$C6,NETWORKDAYS($C6,TODAY()-1)*$I6,0),0) ) -> 0 | N6: =IF($A6="","", IF($C6>N$3+6,0,IF($D6>=N$3,$I6*5,0) -IF($D6>=N$3,IF(O$3>$D6,NETWORKDAYS($D6,O$3)-2,0)*$I6,0) -IF(AND($C6>=N$3,$C6<O$3),($C6-N$3)*$I6,0)) -IF(AND(TODAY()>=N$3,TODAY()<O$3),IF(TODAY()>$C6,NETWORKDAYS($C6,TODAY()-1)*$I6,0),0) ) -> 0 | O6: =IF($A6="","", IF($C6>O$3+6,0,IF($D6>=O$3,$I6*5,0) -IF($D6>=O$3,IF(P$3>$D6,NETWORKDAYS($D6,P$3)-2,0)*$I6,0) -IF(AND($C6>=O$3,$C6<P$3),($C6-O$3)*$I6,0)) -IF(AND(TODAY()>=O$3,TODAY()<P$3),IF(TODAY()>$C6,NETWORKDAYS($C6,TODAY()-1)*$I6,0),0) ) -> 0 | P6: =IF($A6="","", IF($C6>P$3+6,0,IF($D6>=P$3,$I6*5,0) -IF($D6>=P$3,IF(Q$3>$D6,NETWORKDAYS($D6,Q$3)-2,0)*$I6,0) -IF(AND($C6>=P$3,$C6<Q$3),($C6-P$3)*$I6,0)) -IF(AND(TODAY()>=P$3,TODAY()<Q$3),IF(TODAY()>$C6,NETWORKDAYS($C6,TODAY()-1)*$I6,0),0) ) -> 0 | Q6: =IF($A6="","", IF($C6>Q$3+6,0,IF($D6>=Q$3,$I6*5,0) -IF($D6>=Q$3,IF(R$3>$D6,NETWORKDAYS($D6,R$3)-2,0)*$I6,0) -IF(AND($C6>=Q$3,$C6<R$3),($C6-Q$3)*$I6,0)) -IF(AND(TODAY()>=Q$3,TODAY()<R$3),IF(TODAY()>$C6,NETWORKDAYS($C6,TODAY()-1)*$I6,0),0) ) -> 0 | ... U6: =IF($A6="","", IF($C6>U$3+6,0,IF($D6>=U$3,$I6*5,0) -IF($D6>=U$3,IF(V$3>$D6,NETWORKDAYS($D6,V$3)-2,0)*$I6,0) -IF(AND($C6>=U$3,$C6<V$3),($C6-U$3)*$I6,0)) -IF(AND(TODAY()>=U$3,TODAY()<V$3),IF(TODAY()>$C6,NETWORKDAYS($C6,TODAY()-1)*$I6,0),0) ) -> 0 | W6: =SUM(J6:U6) -> -55.75 | X6: =W6=F6 -> FALSE
A7: Camila González | B7: Reclutamiento y selección | C7: 45855 | D7: 45862 | E7: 6 | F7: =IF(E7="","",E7-IF(TODAY()<C7,0,(TODAY()-C7)*I7)) -> -307 | G7: =IF(E7="","",NETWORKDAYS(TODAY(),D7)+1) -> -218 | H7: =IF(E7="","",G7/5) -> -43.6 | I7: =IF(E7="","",E7/((NETWORKDAYS(C7,D7)))) -> 1 | J7: =IF($A7="","", IF($C7>J$3+6,0,IF($D7>=J$3,$I7*5,0) -IF($D7>=J$3,IF(K$3>$D7,NETWORKDAYS($D7,K$3)-2,0)*$I7,0) -IF(AND($C7>=J$3,$C7<K$3),($C7-J$3)*$I7,0)) -IF(AND(TODAY()>=J$3,TODAY()<K$3),IF(TODAY()>$C7,NETWORKDAYS($C7,TODAY()-1)*$I7,0),0) ) -> -223 | K7: =IF($A7="","", IF($C7>K$3+6,0,IF($D7>=K$3,$I7*5,0) -IF($D7>=K$3,IF(L$3>$D7,NETWORKDAYS($D7,L$3)-2,0)*$I7,0) -IF(AND($C7>=K$3,$C7<L$3),($C7-K$3)*$I7,0)) -IF(AND(TODAY()>=K$3,TODAY()<L$3),IF(TODAY()>$C7,NETWORKDAYS($C7,TODAY()-1)*$I7,0),0) ) -> 0 | L7: =IF($A7="","", IF($C7>L$3+6,0,IF($D7>=L$3,$I7*5,0) -IF($D7>=L$3,IF(M$3>$D7,NETWORKDAYS($D7,M$3)-2,0)*$I7,0) -IF(AND($C7>=L$3,$C7<M$3),($C7-L$3)*$I7,0)) -IF(AND(TODAY()>=L$3,TODAY()<M$3),IF(TODAY()>$C7,NETWORKDAYS($C7,TODAY()-1)*$I7,0),0) ) -> 0 | M7: =IF($A7="","", IF($C7>M$3+6,0,IF($D7>=M$3,$I7*5,0) -IF($D7>=M$3,IF(N$3>$D7,NETWORKDAYS($D7,N$3)-2,0)*$I7,0) -IF(AND($C7>=M$3,$C7<N$3),($C7-M$3)*$I7,0)) -IF(AND(TODAY()>=M$3,TODAY()<N$3),IF(TODAY()>$C7,NETWORKDAYS($C7,TODAY()-1)*$I7,0),0) ) -> 0 | N7: =IF($A7="","", IF($C7>N$3+6,0,IF($D7>=N$3,$I7*5,0) -IF($D7>=N$3,IF(O$3>$D7,NETWORKDAYS($D7,O$3)-2,0)*$I7,0) -IF(AND($C7>=N$3,$C7<O$3),($C7-N$3)*$I7,0)) -IF(AND(TODAY()>=N$3,TODAY()<O$3),IF(TODAY()>$C7,NETWORKDAYS($C7,TODAY()-1)*$I7,0),0) ) -> 0 | O7: =IF($A7="","", IF($C7>O$3+6,0,IF($D7>=O$3,$I7*5,0) -IF($D7>=O$3,IF(P$3>$D7,NETWORKDAYS($D7,P$3)-2,0)*$I7,0) -IF(AND($C7>=O$3,$C7<P$3),($C7-O$3)*$I7,0)) -IF(AND(TODAY()>=O$3,TODAY()<P$3),IF(TODAY()>$C7,NETWORKDAYS($C7,TODAY()-1)*$I7,0),0) ) -> 0 | P7: =IF($A7="","", IF($C7>P$3+6,0,IF($D7>=P$3,$I7*5,0) -IF($D7>=P$3,IF(Q$3>$D7,NETWORKDAYS($D7,Q$3)-2,0)*$I7,0) -IF(AND($C7>=P$3,$C7<Q$3),($C7-P$3)*$I7,0)) -IF(AND(TODAY()>=P$3,TODAY()<Q$3),IF(TODAY()>$C7,NETWORKDAYS($C7,TODAY()-1)*$I7,0),0) ) -> 0 | Q7: =IF($A7="","", IF($C7>Q$3+6,0,IF($D7>=Q$3,$I7*5,0) -IF($D7>=Q$3,IF(R$3>$D7,NETWORKDAYS($D7,R$3)-2,0)*$I7,0) -IF(AND($C7>=Q$3,$C7<R$3),($C7-Q$3)*$I7,0)) -IF(AND(TODAY()>=Q$3,TODAY()<R$3),IF(TODAY()>$C7,NETWORKDAYS($C7,TODAY()-1)*$I7,0),0) ) -> 0 | ... U7: =IF($A7="","", IF($C7>U$3+6,0,IF($D7>=U$3,$I7*5,0) -IF($D7>=U$3,IF(V$3>$D7,NETWORKDAYS($D7,V$3)-2,0)*$I7,0) -IF(AND($C7>=U$3,$C7<V$3),($C7-U$3)*$I7,0)) -IF(AND(TODAY()>=U$3,TODAY()<V$3),IF(TODAY()>$C7,NETWORKDAYS($C7,TODAY()-1)*$I7,0),0) ) -> 0 | W7: =SUM(J7:U7) -> -223 | X7: =W7=F7 -> FALSE
A8: Camila González | B8: Cumplimiento legal y normativo | C8: 45848 | D8: 45855 | E8: 3 | F8: =IF(E8="","",E8-IF(TODAY()<C8,0,(TODAY()-C8)*I8)) -> -157 | G8: =IF(E8="","",NETWORKDAYS(TODAY(),D8)+1) -> -223 | H8: =IF(E8="","",G8/5) -> -44.6 | I8: =IF(E8="","",E8/((NETWORKDAYS(C8,D8)))) -> 0.5 | J8: =IF($A8="","", IF($C8>J$3+6,0,IF($D8>=J$3,$I8*5,0) -IF($D8>=J$3,IF(K$3>$D8,NETWORKDAYS($D8,K$3)-2,0)*$I8,0) -IF(AND($C8>=J$3,$C8<K$3),($C8-J$3)*$I8,0)) -IF(AND(TODAY()>=J$3,TODAY()<K$3),IF(TODAY()>$C8,NETWORKDAYS($C8,TODAY()-1)*$I8,0),0) ) -> -114 | K8: =IF($A8="","", IF($C8>K$3+6,0,IF($D8>=K$3,$I8*5,0) -IF($D8>=K$3,IF(L$3>$D8,NETWORKDAYS($D8,L$3)-2,0)*$I8,0) -IF(AND($C8>=K$3,$C8<L$3),($C8-K$3)*$I8,0)) -IF(AND(TODAY()>=K$3,TODAY()<L$3),IF(TODAY()>$C8,NETWORKDAYS($C8,TODAY()-1)*$I8,0),0) ) -> 0 | L8: =IF($A8="","", IF($C8>L$3+6,0,IF($D8>=L$3,$I8*5,0) -IF($D8>=L$3,IF(M$3>$D8,NETWORKDAYS($D8,M$3)-2,0)*$I8,0) -IF(AND($C8>=L$3,$C8<M$3),($C8-L$3)*$I8,0)) -IF(AND(TODAY()>=L$3,TODAY()<M$3),IF(TODAY()>$C8,NETWORKDAYS($C8,TODAY()-1)*$I8,0),0) ) -> 0 | M8: =IF($A8="","", IF($C8>M$3+6,0,IF($D8>=M$3,$I8*5,0) -IF($D8>=M$3,IF(N$3>$D8,NETWORKDAYS($D8,N$3)-2,0)*$I8,0) -IF(AND($C8>=M$3,$C8<N$3),($C8-M$3)*$I8,0)) -IF(AND(TODAY()>=M$3,TODAY()<N$3),IF(TODAY()>$C8,NETWORKDAYS($C8,TODAY()-1)*$I8,0),0) ) -> 0 | N8: =IF($A8="","", IF($C8>N$3+6,0,IF($D8>=N$3,$I8*5,0) -IF($D8>=N$3,IF(O$3>$D8,NETWORKDAYS($D8,O$3)-2,0)*$I8,0) -IF(AND($C8>=N$3,$C8<O$3),($C8-N$3)*$I8,0)) -IF(AND(TODAY()>=N$3,TODAY()<O$3),IF(TODAY()>$C8,NETWORKDAYS($C8,TODAY()-1)*$I8,0),0) ) -> 0 | O8: =IF($A8="","", IF($C8>O$3+6,0,IF($D8>=O$3,$I8*5,0) -IF($D8>=O$3,IF(P$3>$D8,NETWORKDAYS($D8,P$3)-2,0)*$I8,0) -IF(AND($C8>=O$3,$C8<P$3),($C8-O$3)*$I8,0)) -IF(AND(TODAY()>=O$3,TODAY()<P$3),IF(TODAY()>$C8,NETWORKDAYS($C8,TODAY()-1)*$I8,0),0) ) -> 0 | P8: =IF($A8="","", IF($C8>P$3+6,0,IF($D8>=P$3,$I8*5,0) -IF($D8>=P$3,IF(Q$3>$D8,NETWORKDAYS($D8,Q$3)-2,0)*$I8,0) -IF(AND($C8>=P$3,$C8<Q$3),($C8-P$3)*$I8,0)) -IF(AND(TODAY()>=P$3,TODAY()<Q$3),IF(TODAY()>$C8,NETWORKDAYS($C8,TODAY()-1)*$I8,0),0) ) -> 0 | Q8: =IF($A8="","", IF($C8>Q$3+6,0,IF($D8>=Q$3,$I8*5,0) -IF($D8>=Q$3,IF(R$3>$D8,NETWORKDAYS($D8,R$3)-2,0)*$I8,0) -IF(AND($C8>=Q$3,$C8<R$3),($C8-Q$3)*$I8,0)) -IF(AND(TODAY()>=Q$3,TODAY()<R$3),IF(TODAY()>$C8,NETWORKDAYS($C8,TODAY()-1)*$I8,0),0) ) -> 0 | ... U8: =IF($A8="","", IF($C8>U$3+6,0,IF($D8>=U$3,$I8*5,0) -IF($D8>=U$3,IF(V$3>$D8,NETWORKDAYS($D8,V$3)-2,0)*$I8,0) -IF(AND($C8>=U$3,$C8<V$3),($C8-U$3)*$I8,0)) -IF(AND(TODAY()>=U$3,TODAY()<V$3),IF(TODAY()>$C8,NETWORKDAYS($C8,TODAY()-1)*$I8,0),0) ) -> 0 | W8: =SUM(J8:U8) -> -114 | X8: =W8=F8 -> FALSE
A9: Camila González | B9: Gestión de salud y seguridad ocupacional | C9: 45848 | D9: 45855 | E9: 2.5 | F9: =IF(E9="","",E9-IF(TODAY()<C9,0,(TODAY()-C9)*I9)) -> -130.83333 | G9: =IF(E9="","",NETWORKDAYS(TODAY(),D9)+1) -> -223 | H9: =IF(E9="","",G9/5) -> -44.6 | I9: =IF(E9="","",E9/((NETWORKDAYS(C9,D9)))) -> 0.41666667 | J9: =IF($A9="","", IF($C9>J$3+6,0,IF($D9>=J$3,$I9*5,0) -IF($D9>=J$3,IF(K$3>$D9,NETWORKDAYS($D9,K$3)-2,0)*$I9,0) -IF(AND($C9>=J$3,$C9<K$3),($C9-J$3)*$I9,0)) -IF(AND(TODAY()>=J$3,TODAY()<K$3),IF(TODAY()>$C9,NETWORKDAYS($C9,TODAY()-1)*$I9,0),0) ) -> -95 | K9: =IF($A9="","", IF($C9>K$3+6,0,IF($D9>=K$3,$I9*5,0) -IF($D9>=K$3,IF(L$3>$D9,NETWORKDAYS($D9,L$3)-2,0)*$I9,0) -IF(AND($C9>=K$3,$C9<L$3),($C9-K$3)*$I9,0)) -IF(AND(TODAY()>=K$3,TODAY()<L$3),IF(TODAY()>$C9,NETWORKDAYS($C9,TODAY()-1)*$I9,0),0) ) -> 0 | L9: =IF($A9="","", IF($C9>L$3+6,0,IF($D9>=L$3,$I9*5,0) -IF($D9>=L$3,IF(M$3>$D9,NETWORKDAYS($D9,M$3)-2,0)*$I9,0) -IF(AND($C9>=L$3,$C9<M$3),($C9-L$3)*$I9,0)) -IF(AND(TODAY()>=L$3,TODAY()<M$3),IF(TODAY()>$C9,NETWORKDAYS($C9,TODAY()-1)*$I9,0),0) ) -> 0 | M9: =IF($A9="","", IF($C9>M$3+6,0,IF($D9>=M$3,$I9*5,0) -IF($D9>=M$3,IF(N$3>$D9,NETWORKDAYS($D9,N$3)-2,0)*$I9,0) -IF(AND($C9>=M$3,$C9<N$3),($C9-M$3)*$I9,0)) -IF(AND(TODAY()>=M$3,TODAY()<N$3),IF(TODAY()>$C9,NETWORKDAYS($C9,TODAY()-1)*$I9,0),0) ) -> 0 | N9: =IF($A9="","", IF($C9>N$3+6,0,IF($D9>=N$3,$I9*5,0) -IF($D9>=N$3,IF(O$3>$D9,NETWORKDAYS($D9,O$3)-2,0)*$I9,0) -IF(AND($C9>=N$3,$C9<O$3),($C9-N$3)*$I9,0)) -IF(AND(TODAY()>=N$3,TODAY()<O$3),IF(TODAY()>$C9,NETWORKDAYS($C9,TODAY()-1)*$I9,0),0) ) -> 0 | O9: =IF($A9="","", IF($C9>O$3+6,0,IF($D9>=O$3,$I9*5,0) -IF($D9>=O$3,IF(P$3>$D9,NETWORKDAYS($D9,P$3)-2,0)*$I9,0) -IF(AND($C9>=O$3,$C9<P$3),($C9-O$3)*$I9,0)) -IF(AND(TODAY()>=O$3,TODAY()<P$3),IF(TODAY()>$C9,NETWORKDAYS($C9,TODAY()-1)*$I9,0),0) ) -> 0 | P9: =IF($A9="","", IF($C9>P$3+6,0,IF($D9>=P$3,$I9*5,0) -IF($D9>=P$3,IF(Q$3>$D9,NETWORKDAYS($D9,Q$3)-2,0)*$I9,0) -IF(AND($C9>=P$3,$C9<Q$3),($C9-P$3)*$I9,0)) -IF(AND(TODAY()>=P$3,TODAY()<Q$3),IF(TODAY()>$C9,NETWORKDAYS($C9,TODAY()-1)*$I9,0),0) ) -> 0 | Q9: =IF($A9="","", IF($C9>Q$3+6,0,IF($D9>=Q$3,$I9*5,0) -IF($D9>=Q$3,IF(R$3>$D9,NETWORKDAYS($D9,R$3)-2,0)*$I9,0) -IF(AND($C9>=Q$3,$C9<R$3),($C9-Q$3)*$I9,0)) -IF(AND(TODAY()>=Q$3,TODAY()<R$3),IF(TODAY()>$C9,NETWORKDAYS($C9,TODAY()-1)*$I9,0),0) ) -> 0 | ... U9: =IF($A9="","", IF($C9>U$3+6,0,IF($D9>=U$3,$I9*5,0) -IF($D9>=U$3,IF(V$3>$D9,NETWORKDAYS($D9,V$3)-2,0)*$I9,0) -IF(AND($C9>=U$3,$C9<V$3),($C9-U$3)*$I9,0)) -IF(AND(TODAY()>=U$3,TODAY()<V$3),IF(TODAY()>$C9,NETWORKDAYS($C9,TODAY()-1)*$I9,0),0) ) -> 0 | W9: =SUM(J9:U9) -> -95 | X9: =W9=F9 -> FALSE
A10: Camila González | B10: Cumplimiento legal y normativo | C10: 45862 | D10: 45869 | E10: 3 | F10: =IF(E10="","",E10-IF(TODAY()<C10,0,(TODAY()-C10)*I10)) -> -150 | G10: =IF(E10="","",NETWORKDAYS(TODAY(),D10)+1) -> -213 | H10: =IF(E10="","",G10/5) -> -42.6 | I10: =IF(E10="","",E10/((NETWORKDAYS(C10,D10)))) -> 0.5 | J10: =IF($A10="","", IF($C10>J$3+6,0,IF($D10>=J$3,$I10*5,0) -IF($D10>=J$3,IF(K$3>$D10,NETWORKDAYS($D10,K$3)-2,0)*$I10,0) -IF(AND($C10>=J$3,$C10<K$3),($C10-J$3)*$I10,0)) -IF(AND(TODAY()>=J$3,TODAY()<K$3),IF(TODAY()>$C10,NETWORKDAYS($C10,TODAY()-1)*$I10,0),0) ) -> -109 | K10: =IF($A10="","", IF($C10>K$3+6,0,IF($D10>=K$3,$I10*5,0) -IF($D10>=K$3,IF(L$3>$D10,NETWORKDAYS($D10,L$3)-2,0)*$I10,0) -IF(AND($C10>=K$3,$C10<L$3),($C10-K$3)*$I10,0)) -IF(AND(TODAY()>=K$3,TODAY()<L$3),IF(TODAY()>$C10,NETWORKDAYS($C10,TODAY()-1)*$I10,0),0) ) -> 0 | L10: =IF($A10="","", IF($C10>L$3+6,0,IF($D10>=L$3,$I10*5,0) -IF($D10>=L$3,IF(M$3>$D10,NETWORKDAYS($D10,M$3)-2,0)*$I10,0) -IF(AND($C10>=L$3,$C10<M$3),($C10-L$3)*$I10,0)) -IF(AND(TODAY()>=L$3,TODAY()<M$3),IF(TODAY()>$C10,NETWORKDAYS($C10,TODAY()-1)*$I10,0),0) ) -> 0 | M10: =IF($A10="","", IF($C10>M$3+6,0,IF($D10>=M$3,$I10*5,0) -IF($D10>=M$3,IF(N$3>$D10,NETWORKDAYS($D10,N$3)-2,0)*$I10,0) -IF(AND($C10>=M$3,$C10<N$3),($C10-M$3)*$I10,0)) -IF(AND(TODAY()>=M$3,TODAY()<N$3),IF(TODAY()>$C10,NETWORKDAYS($C10,TODAY()-1)*$I10,0),0) ) -> 0 | N10: =IF($A10="","", IF($C10>N$3+6,0,IF($D10>=N$3,$I10*5,0) -IF($D10>=N$3,IF(O$3>$D10,NETWORKDAYS($D10,O$3)-2,0)*$I10,0) -IF(AND($C10>=N$3,$C10<O$3),($C10-N$3)*$I10,0)) -IF(AND(TODAY()>=N$3,TODAY()<O$3),IF(TODAY()>$C10,NETWORKDAYS($C10,TODAY()-1)*$I10,0),0) ) -> 0 | O10: =IF($A10="","", IF($C10>O$3+6,0,IF($D10>=O$3,$I10*5,0) -IF($D10>=O$3,IF(P$3>$D10,NETWORKDAYS($D10,P$3)-2,0)*$I10,0) -IF(AND($C10>=O$3,$C10<P$3),($C10-O$3)*$I10,0)) -IF(AND(TODAY()>=O$3,TODAY()<P$3),IF(TODAY()>$C10,NETWORKDAYS($C10,TODAY()-1)*$I10,0),0) ) -> 0 | P10: =IF($A10="","", IF($C10>P$3+6,0,IF($D10>=P$3,$I10*5,0) -IF($D10>=P$3,IF(Q$3>$D10,NETWORKDAYS($D10,Q$3)-2,0)*$I10,0) -IF(AND($C10>=P$3,$C10<Q$3),($C10-P$3)*$I10,0)) -IF(AND(TODAY()>=P$3,TODAY()<Q$3),IF(TODAY()>$C10,NETWORKDAYS($C10,TODAY()-1)*$I10,0),0) ) -> 0 | Q10: =IF($A10="","", IF($C10>Q$3+6,0,IF($D10>=Q$3,$I10*5,0) -IF($D10>=Q$3,IF(R$3>$D10,NETWORKDAYS($D10,R$3)-2,0)*$I10,0) -IF(AND($C10>=Q$3,$C10<R$3),($C10-Q$3)*$I10,0)) -IF(AND(TODAY()>=Q$3,TODAY()<R$3),IF(TODAY()>$C10,NETWORKDAYS($C10,TODAY()-1)*$I10,0),0) ) -> 0 | ... U10: =IF($A10="","", IF($C10>U$3+6,0,IF($D10>=U$3,$I10*5,0) -IF($D10>=U$3,IF(V$3>$D10,NETWORKDAYS($D10,V$3)-2,0)*$I10,0) -IF(AND($C10>=U$3,$C10<V$3),($C10-U$3)*$I10,0)) -IF(AND(TODAY()>=U$3,TODAY()<V$3),IF(TODAY()>$C10,NETWORKDAYS($C10,TODAY()-1)*$I10,0),0) ) -> 0 | W10: =SUM(J10:U10) -> -109 | X10: =W10=F10 -> FALSE
A11: Camila González | B11: Capacitación y desarrollo | C11: 45862 | D11: 45869 | E11: 3 | F11: =IF(E11="","",E11-IF(TODAY()<C11,0,(TODAY()-C11)*I11)) -> -150 | G11: =IF(E11="","",NETWORKDAYS(TODAY(),D11)+1) -> -213 | H11: =IF(E11="","",G11/5) -> -42.6 | I11: =IF(E11="","",E11/((NETWORKDAYS(C11,D11)))) -> 0.5 | J11: =IF($A11="","", IF($C11>J$3+6,0,IF($D11>=J$3,$I11*5,0) -IF($D11>=J$3,IF(K$3>$D11,NETWORKDAYS($D11,K$3)-2,0)*$I11,0) -IF(AND($C11>=J$3,$C11<K$3),($C11-J$3)*$I11,0)) -IF(AND(TODAY()>=J$3,TODAY()<K$3),IF(TODAY()>$C11,NETWORKDAYS($C11,TODAY()-1)*$I11,0),0) ) -> -109 | K11: =IF($A11="","", IF($C11>K$3+6,0,IF($D11>=K$3,$I11*5,0) -IF($D11>=K$3,IF(L$3>$D11,NETWORKDAYS($D11,L$3)-2,0)*$I11,0) -IF(AND($C11>=K$3,$C11<L$3),($C11-K$3)*$I11,0)) -IF(AND(TODAY()>=K$3,TODAY()<L$3),IF(TODAY()>$C11,NETWORKDAYS($C11,TODAY()-1)*$I11,0),0) ) -> 0 | L11: =IF($A11="","", IF($C11>L$3+6,0,IF($D11>=L$3,$I11*5,0) -IF($D11>=L$3,IF(M$3>$D11,NETWORKDAYS($D11,M$3)-2,0)*$I11,0) -IF(AND($C11>=L$3,$C11<M$3),($C11-L$3)*$I11,0)) -IF(AND(TODAY()>=L$3,TODAY()<M$3),IF(TODAY()>$C11,NETWORKDAYS($C11,TODAY()-1)*$I11,0),0) ) -> 0 | M11: =IF($A11="","", IF($C11>M$3+6,0,IF($D11>=M$3,$I11*5,0) -IF($D11>=M$3,IF(N$3>$D11,NETWORKDAYS($D11,N$3)-2,0)*$I11,0) -IF(AND($C11>=M$3,$C11<N$3),($C11-M$3)*$I11,0)) -IF(AND(TODAY()>=M$3,TODAY()<N$3),IF(TODAY()>$C11,NETWORKDAYS($C11,TODAY()-1)*$I11,0),0) ) -> 0 | N11: =IF($A11="","", IF($C11>N$3+6,0,IF($D11>=N$3,$I11*5,0) -IF($D11>=N$3,IF(O$3>$D11,NETWORKDAYS($D11,O$3)-2,0)*$I11,0) -IF(AND($C11>=N$3,$C11<O$3),($C11-N$3)*$I11,0)) -IF(AND(TODAY()>=N$3,TODAY()<O$3),IF(TODAY()>$C11,NETWORKDAYS($C11,TODAY()-1)*$I11,0),0) ) -> 0 | O11: =IF($A11="","", IF($C11>O$3+6,0,IF($D11>=O$3,$I11*5,0) -IF($D11>=O$3,IF(P$3>$D11,NETWORKDAYS($D11,P$3)-2,0)*$I11,0) -IF(AND($C11>=O$3,$C11<P$3),($C11-O$3)*$I11,0)) -IF(AND(TODAY()>=O$3,TODAY()<P$3),IF(TODAY()>$C11,NETWORKDAYS($C11,TODAY()-1)*$I11,0),0) ) -> 0 | P11: =IF($A11="","", IF($C11>P$3+6,0,IF($D11>=P$3,$I11*5,0) -IF($D11>=P$3,IF(Q$3>$D11,NETWORKDAYS($D11,Q$3)-2,0)*$I11,0) -IF(AND($C11>=P$3,$C11<Q$3),($C11-P$3)*$I11,0)) -IF(AND(TODAY()>=P$3,TODAY()<Q$3),IF(TODAY()>$C11,NETWORKDAYS($C11,TODAY()-1)*$I11,0),0) ) -> 0 | Q11: =IF($A11="","", IF($C11>Q$3+6,0,IF($D11>=Q$3,$I11*5,0) -IF($D11>=Q$3,IF(R$3>$D11,NETWORKDAYS($D11,R$3)-2,0)*$I11,0) -IF(AND($C11>=Q$3,$C11<R$3),($C11-Q$3)*$I11,0)) -IF(AND(TODAY()>=Q$3,TODAY()<R$3),IF(TODAY()>$C11,NETWORKDAYS($C11,TODAY()-1)*$I11,0),0) ) -> 0 | ... U11: =IF($A11="","", IF($C11>U$3+6,0,IF($D11>=U$3,$I11*5,0) -IF($D11>=U$3,IF(V$3>$D11,NETWORKDAYS($D11,V$3)-2,0)*$I11,0) -IF(AND($C11>=U$3,$C11<V$3),($C11-U$3)*$I11,0)) -IF(AND(TODAY()>=U$3,TODAY()<V$3),IF(TODAY()>$C11,NETWORKDAYS($C11,TODAY()-1)*$I11,0),0) ) -> 0 | W11: =SUM(J11:U11) -> -109 | X11: =W11=F11 -> FALSE
A12: Camila González | B12: Administración de personal | C12: 45848 | D12: 45855 | E12: 3 | F12: =IF(E12="","",E12-IF(TODAY()<C12,0,(TODAY()-C12)*I12)) -> -157 | G12: =IF(E12="","",NETWORKDAYS(TODAY(),D12)+1) -> -223 | H12: =IF(E12="","",G12/5) -> -44.6 | I12: =IF(E12="","",E12/((NETWORKDAYS(C12,D12)))) -> 0.5 | J12: =IF($A12="","", IF($C12>J$3+6,0,IF($D12>=J$3,$I12*5,0) -IF($D12>=J$3,IF(K$3>$D12,NETWORKDAYS($D12,K$3)-2,0)*$I12,0) -IF(AND($C12>=J$3,$C12<K$3),($C12-J$3)*$I12,0)) -IF(AND(TODAY()>=J$3,TODAY()<K$3),IF(TODAY()>$C12,NETWORKDAYS($C12,TODAY()-1)*$I12,0),0) ) -> -114 | K12: =IF($A12="","", IF($C12>K$3+6,0,IF($D12>=K$3,$I12*5,0) -IF($D12>=K$3,IF(L$3>$D12,NETWORKDAYS($D12,L$3)-2,0)*$I12,0) -IF(AND($C12>=K$3,$C12<L$3),($C12-K$3)*$I12,0)) -IF(AND(TODAY()>=K$3,TODAY()<L$3),IF(TODAY()>$C12,NETWORKDAYS($C12,TODAY()-1)*$I12,0),0) ) -> 0 | L12: =IF($A12="","", IF($C12>L$3+6,0,IF($D12>=L$3,$I12*5,0) -IF($D12>=L$3,IF(M$3>$D12,NETWORKDAYS($D12,M$3)-2,0)*$I12,0) -IF(AND($C12>=L$3,$C12<M$3),($C12-L$3)*$I12,0)) -IF(AND(TODAY()>=L$3,TODAY()<M$3),IF(TODAY()>$C12,NETWORKDAYS($C12,TODAY()-1)*$I12,0),0) ) -> 0 | M12: =IF($A12="","", IF($C12>M$3+6,0,IF($D12>=M$3,$I12*5,0) -IF($D12>=M$3,IF(N$3>$D12,NETWORKDAYS($D12,N$3)-2,0)*$I12,0) -IF(AND($C12>=M$3,$C12<N$3),($C12-M$3)*$I12,0)) -IF(AND(TODAY()>=M$3,TODAY()<N$3),IF(TODAY()>$C12,NETWORKDAYS($C12,TODAY()-1)*$I12,0),0) ) -> 0 | N12: =IF($A12="","", IF($C12>N$3+6,0,IF($D12>=N$3,$I12*5,0) -IF($D12>=N$3,IF(O$3>$D12,NETWORKDAYS($D12,O$3)-2,0)*$I12,0) -IF(AND($C12>=N$3,$C12<O$3),($C12-N$3)*$I12,0)) -IF(AND(TODAY()>=N$3,TODAY()<O$3),IF(TODAY()>$C12,NETWORKDAYS($C12,TODAY()-1)*$I12,0),0) ) -> 0 | O12: =IF($A12="","", IF($C12>O$3+6,0,IF($D12>=O$3,$I12*5,0) -IF($D12>=O$3,IF(P$3>$D12,NETWORKDAYS($D12,P$3)-2,0)*$I12,0) -IF(AND($C12>=O$3,$C12<P$3),($C12-O$3)*$I12,0)) -IF(AND(TODAY()>=O$3,TODAY()<P$3),IF(TODAY()>$C12,NETWORKDAYS($C12,TODAY()-1)*$I12,0),0) ) -> 0 | P12: =IF($A12="","", IF($C12>P$3+6,0,IF($D12>=P$3,$I12*5,0) -IF($D12>=P$3,IF(Q$3>$D12,NETWORKDAYS($D12,Q$3)-2,0)*$I12,0) -IF(AND($C12>=P$3,$C12<Q$3),($C12-P$3)*$I12,0)) -IF(AND(TODAY()>=P$3,TODAY()<Q$3),IF(TODAY()>$C12,NETWORKDAYS($C12,TODAY()-1)*$I12,0),0) ) -> 0 | Q12: =IF($A12="","", IF($C12>Q$3+6,0,IF($D12>=Q$3,$I12*5,0) -IF($D12>=Q$3,IF(R$3>$D12,NETWORKDAYS($D12,R$3)-2,0)*$I12,0) -IF(AND($C12>=Q$3,$C12<R$3),($C12-Q$3)*$I12,0)) -IF(AND(TODAY()>=Q$3,TODAY()<R$3),IF(TODAY()>$C12,NETWORKDAYS($C12,TODAY()-1)*$I12,0),0) ) -> 0 | ... U12: =IF($A12="","", IF($C12>U$3+6,0,IF($D12>=U$3,$I12*5,0) -IF($D12>=U$3,IF(V$3>$D12,NETWORKDAYS($D12,V$3)-2,0)*$I12,0) -IF(AND($C12>=U$3,$C12<V$3),($C12-U$3)*$I12,0)) -IF(AND(TODAY()>=U$3,TODAY()<V$3),IF(TODAY()>$C12,NETWORKDAYS($C12,TODAY()-1)*$I12,0),0) ) -> 0 | W12: =SUM(J12:U12) -> -114 | X12: =W12=F12 -> FALSE
A13: Camila González | B13: Gestión de remuneraciones y beneficios | C13: 45848 | D13: 45855 | E13: 9 | F13: =IF(E13="","",E13-IF(TODAY()<C13,0,(TODAY()-C13)*I13)) -> -471 | G13: =IF(E13="","",NETWORKDAYS(TODAY(),D13)+1) -> -223 | H13: =IF(E13="","",G13/5) -> -44.6 | I13: =IF(E13="","",E13/((NETWORKDAYS(C13,D13)))) -> 1.5 | J13: =IF($A13="","", IF($C13>J$3+6,0,IF($D13>=J$3,$I13*5,0) -IF($D13>=J$3,IF(K$3>$D13,NETWORKDAYS($D13,K$3)-2,0)*$I13,0) -IF(AND($C13>=J$3,$C13<K$3),($C13-J$3)*$I13,0)) -IF(AND(TODAY()>=J$3,TODAY()<K$3),IF(TODAY()>$C13,NETWORKDAYS($C13,TODAY()-1)*$I13,0),0) ) -> -342 | K13: =IF($A13="","", IF($C13>K$3+6,0,IF($D13>=K$3,$I13*5,0) -IF($D13>=K$3,IF(L$3>$D13,NETWORKDAYS($D13,L$3)-2,0)*$I13,0) -IF(AND($C13>=K$3,$C13<L$3),($C13-K$3)*$I13,0)) -IF(AND(TODAY()>=K$3,TODAY()<L$3),IF(TODAY()>$C13,NETWORKDAYS($C13,TODAY()-1)*$I13,0),0) ) -> 0 | L13: =IF($A13="","", IF($C13>L$3+6,0,IF($D13>=L$3,$I13*5,0) -IF($D13>=L$3,IF(M$3>$D13,NETWORKDAYS($D13,M$3)-2,0)*$I13,0) -IF(AND($C13>=L$3,$C13<M$3),($C13-L$3)*$I13,0)) -IF(AND(TODAY()>=L$3,TODAY()<M$3),IF(TODAY()>$C13,NETWORKDAYS($C13,TODAY()-1)*$I13,0),0) ) -> 0 | M13: =IF($A13="","", IF($C13>M$3+6,0,IF($D13>=M$3,$I13*5,0) -IF($D13>=M$3,IF(N$3>$D13,NETWORKDAYS($D13,N$3)-2,0)*$I13,0) -IF(AND($C13>=M$3,$C13<N$3),($C13-M$3)*$I13,0)) -IF(AND(TODAY()>=M$3,TODAY()<N$3),IF(TODAY()>$C13,NETWORKDAYS($C13,TODAY()-1)*$I13,0),0) ) -> 0 | N13: =IF($A13="","", IF($C13>N$3+6,0,IF($D13>=N$3,$I13*5,0) -IF($D13>=N$3,IF(O$3>$D13,NETWORKDAYS($D13,O$3)-2,0)*$I13,0) -IF(AND($C13>=N$3,$C13<O$3),($C13-N$3)*$I13,0)) -IF(AND(TODAY()>=N$3,TODAY()<O$3),IF(TODAY()>$C13,NETWORKDAYS($C13,TODAY()-1)*$I13,0),0) ) -> 0 | O13: =IF($A13="","", IF($C13>O$3+6,0,IF($D13>=O$3,$I13*5,0) -IF($D13>=O$3,IF(P$3>$D13,NETWORKDAYS($D13,P$3)-2,0)*$I13,0) -IF(AND($C13>=O$3,$C13<P$3),($C13-O$3)*$I13,0)) -IF(AND(TODAY()>=O$3,TODAY()<P$3),IF(TODAY()>$C13,NETWORKDAYS($C13,TODAY()-1)*$I13,0),0) ) -> 0 | P13: =IF($A13="","", IF($C13>P$3+6,0,IF($D13>=P$3,$I13*5,0) -IF($D13>=P$3,IF(Q$3>$D13,NETWORKDAYS($D13,Q$3)-2,0)*$I13,0) -IF(AND($C13>=P$3,$C13<Q$3),($C13-P$3)*$I13,0)) -IF(AND(TODAY()>=P$3,TODAY()<Q$3),IF(TODAY()>$C13,NETWORKDAYS($C13,TODAY()-1)*$I13,0),0) ) -> 0 | Q13: =IF($A13="","", IF($C13>Q$3+6,0,IF($D13>=Q$3,$I13*5,0) -IF($D13>=Q$3,IF(R$3>$D13,NETWORKDAYS($D13,R$3)-2,0)*$I13,0) -IF(AND($C13>=Q$3,$C13<R$3),($C13-Q$3)*$I13,0)) -IF(AND(TODAY()>=Q$3,TODAY()<R$3),IF(TODAY()>$C13,NETWORKDAYS($C13,TODAY()-1)*$I13,0),0) ) -> 0 | ... U13: =IF($A13="","", IF($C13>U$3+6,0,IF($D13>=U$3,$I13*5,0) -IF($D13>=U$3,IF(V$3>$D13,NETWORKDAYS($D13,V$3)-2,0)*$I13,0) -IF(AND($C13>=U$3,$C13<V$3),($C13-U$3)*$I13,0)) -IF(AND(TODAY()>=U$3,TODAY()<V$3),IF(TODAY()>$C13,NETWORKDAYS($C13,TODAY()-1)*$I13,0),0) ) -> 0 | W13: =SUM(J13:U13) -> -342 | X13: =W13=F13 -> FALSE
A14: Camila González | B14: Administración de personal | C14: 45862 | D14: 45869 | E14: 3 | F14: =IF(E14="","",E14-IF(TODAY()<C14,0,(TODAY()-C14)*I14)) -> -150 | G14: =IF(E14="","",NETWORKDAYS(TODAY(),D14)+1) -> -213 | H14: =IF(E14="","",G14/5) -> -42.6 | I14: =IF(E14="","",E14/((NETWORKDAYS(C14,D14)))) -> 0.5 | J14: =IF($A14="","", IF($C14>J$3+6,0,IF($D14>=J$3,$I14*5,0) -IF($D14>=J$3,IF(K$3>$D14,NETWORKDAYS($D14,K$3)-2,0)*$I14,0) -IF(AND($C14>=J$3,$C14<K$3),($C14-J$3)*$I14,0)) -IF(AND(TODAY()>=J$3,TODAY()<K$3),IF(TODAY()>$C14,NETWORKDAYS($C14,TODAY()-1)*$I14,0),0) ) -> -109 | K14: =IF($A14="","", IF($C14>K$3+6,0,IF($D14>=K$3,$I14*5,0) -IF($D14>=K$3,IF(L$3>$D14,NETWORKDAYS($D14,L$3)-2,0)*$I14,0) -IF(AND($C14>=K$3,$C14<L$3),($C14-K$3)*$I14,0)) -IF(AND(TODAY()>=K$3,TODAY()<L$3),IF(TODAY()>$C14,NETWORKDAYS($C14,TODAY()-1)*$I14,0),0) ) -> 0 | L14: =IF($A14="","", IF($C14>L$3+6,0,IF($D14>=L$3,$I14*5,0) -IF($D14>=L$3,IF(M$3>$D14,NETWORKDAYS($D14,M$3)-2,0)*$I14,0) -IF(AND($C14>=L$3,$C14<M$3),($C14-L$3)*$I14,0)) -IF(AND(TODAY()>=L$3,TODAY()<M$3),IF(TODAY()>$C14,NETWORKDAYS($C14,TODAY()-1)*$I14,0),0) ) -> 0 | M14: =IF($A14="","", IF($C14>M$3+6,0,IF($D14>=M$3,$I14*5,0) -IF($D14>=M$3,IF(N$3>$D14,NETWORKDAYS($D14,N$3)-2,0)*$I14,0) -IF(AND($C14>=M$3,$C14<N$3),($C14-M$3)*$I14,0)) -IF(AND(TODAY()>=M$3,TODAY()<N$3),IF(TODAY()>$C14,NETWORKDAYS($C14,TODAY()-1)*$I14,0),0) ) -> 0 | N14: =IF($A14="","", IF($C14>N$3+6,0,IF($D14>=N$3,$I14*5,0) -IF($D14>=N$3,IF(O$3>$D14,NETWORKDAYS($D14,O$3)-2,0)*$I14,0) -IF(AND($C14>=N$3,$C14<O$3),($C14-N$3)*$I14,0)) -IF(AND(TODAY()>=N$3,TODAY()<O$3),IF(TODAY()>$C14,NETWORKDAYS($C14,TODAY()-1)*$I14,0),0) ) -> 0 | O14: =IF($A14="","", IF($C14>O$3+6,0,IF($D14>=O$3,$I14*5,0) -IF($D14>=O$3,IF(P$3>$D14,NETWORKDAYS($D14,P$3)-2,0)*$I14,0) -IF(AND($C14>=O$3,$C14<P$3),($C14-O$3)*$I14,0)) -IF(AND(TODAY()>=O$3,TODAY()<P$3),IF(TODAY()>$C14,NETWORKDAYS($C14,TODAY()-1)*$I14,0),0) ) -> 0 | P14: =IF($A14="","", IF($C14>P$3+6,0,IF($D14>=P$3,$I14*5,0) -IF($D14>=P$3,IF(Q$3>$D14,NETWORKDAYS($D14,Q$3)-2,0)*$I14,0) -IF(AND($C14>=P$3,$C14<Q$3),($C14-P$3)*$I14,0)) -IF(AND(TODAY()>=P$3,TODAY()<Q$3),IF(TODAY()>$C14,NETWORKDAYS($C14,TODAY()-1)*$I14,0),0) ) -> 0 | Q14: =IF($A14="","", IF($C14>Q$3+6,0,IF($D14>=Q$3,$I14*5,0) -IF($D14>=Q$3,IF(R$3>$D14,NETWORKDAYS($D14,R$3)-2,0)*$I14,0) -IF(AND($C14>=Q$3,$C14<R$3),($C14-Q$3)*$I14,0)) -IF(AND(TODAY()>=Q$3,TODAY()<R$3),IF(TODAY()>$C14,NETWORKDAYS($C14,TODAY()-1)*$I14,0),0) ) -> 0 | ... U14: =IF($A14="","", IF($C14>U$3+6,0,IF($D14>=U$3,$I14*5,0) -IF($D14>=U$3,IF(V$3>$D14,NETWORKDAYS($D14,V$3)-2,0)*$I14,0) -IF(AND($C14>=U$3,$C14<V$3),($C14-U$3)*$I14,0)) -IF(AND(TODAY()>=U$3,TODAY()<V$3),IF(TODAY()>$C14,NETWORKDAYS($C14,TODAY()-1)*$I14,0),0) ) -> 0 | W14: =SUM(J14:U14) -> -109 | X14: =W14=F14 -> FALSE
A15: Camila González | B15: Reclutamiento y selección | C15: 45862 | D15: 45869 | E15: 6 | F15: =IF(E15="","",E15-IF(TODAY()<C15,0,(TODAY()-C15)*I15)) -> -300 | G15: =IF(E15="","",NETWORKDAYS(TODAY(),D15)+1) -> -213 | H15: =IF(E15="","",G15/5) -> -42.6 | I15: =IF(E15="","",E15/((NETWORKDAYS(C15,D15)))) -> 1 | J15: =IF($A15="","", IF($C15>J$3+6,0,IF($D15>=J$3,$I15*5,0) -IF($D15>=J$3,IF(K$3>$D15,NETWORKDAYS($D15,K$3)-2,0)*$I15,0) -IF(AND($C15>=J$3,$C15<K$3),($C15-J$3)*$I15,0)) -IF(AND(TODAY()>=J$3,TODAY()<K$3),IF(TODAY()>$C15,NETWORKDAYS($C15,TODAY()-1)*$I15,0),0) ) -> -218 | K15: =IF($A15="","", IF($C15>K$3+6,0,IF($D15>=K$3,$I15*5,0) -IF($D15>=K$3,IF(L$3>$D15,NETWORKDAYS($D15,L$3)-2,0)*$I15,0) -IF(AND($C15>=K$3,$C15<L$3),($C15-K$3)*$I15,0)) -IF(AND(TODAY()>=K$3,TODAY()<L$3),IF(TODAY()>$C15,NETWORKDAYS($C15,TODAY()-1)*$I15,0),0) ) -> 0 | L15: =IF($A15="","", IF($C15>L$3+6,0,IF($D15>=L$3,$I15*5,0) -IF($D15>=L$3,IF(M$3>$D15,NETWORKDAYS($D15,M$3)-2,0)*$I15,0) -IF(AND($C15>=L$3,$C15<M$3),($C15-L$3)*$I15,0)) -IF(AND(TODAY()>=L$3,TODAY()<M$3),IF(TODAY()>$C15,NETWORKDAYS($C15,TODAY()-1)*$I15,0),0) ) -> 0 | M15: =IF($A15="","", IF($C15>M$3+6,0,IF($D15>=M$3,$I15*5,0) -IF($D15>=M$3,IF(N$3>$D15,NETWORKDAYS($D15,N$3)-2,0)*$I15,0) -IF(AND($C15>=M$3,$C15<N$3),($C15-M$3)*$I15,0)) -IF(AND(TODAY()>=M$3,TODAY()<N$3),IF(TODAY()>$C15,NETWORKDAYS($C15,TODAY()-1)*$I15,0),0) ) -> 0 | N15: =IF($A15="","", IF($C15>N$3+6,0,IF($D15>=N$3,$I15*5,0) -IF($D15>=N$3,IF(O$3>$D15,NETWORKDAYS($D15,O$3)-2,0)*$I15,0) -IF(AND($C15>=N$3,$C15<O$3),($C15-N$3)*$I15,0)) -IF(AND(TODAY()>=N$3,TODAY()<O$3),IF(TODAY()>$C15,NETWORKDAYS($C15,TODAY()-1)*$I15,0),0) ) -> 0 | O15: =IF($A15="","", IF($C15>O$3+6,0,IF($D15>=O$3,$I15*5,0) -IF($D15>=O$3,IF(P$3>$D15,NETWORKDAYS($D15,P$3)-2,0)*$I15,0) -IF(AND($C15>=O$3,$C15<P$3),($C15-O$3)*$I15,0)) -IF(AND(TODAY()>=O$3,TODAY()<P$3),IF(TODAY()>$C15,NETWORKDAYS($C15,TODAY()-1)*$I15,0),0) ) -> 0 | P15: =IF($A15="","", IF($C15>P$3+6,0,IF($D15>=P$3,$I15*5,0) -IF($D15>=P$3,IF(Q$3>$D15,NETWORKDAYS($D15,Q$3)-2,0)*$I15,0) -IF(AND($C15>=P$3,$C15<Q$3),($C15-P$3)*$I15,0)) -IF(AND(TODAY()>=P$3,TODAY()<Q$3),IF(TODAY()>$C15,NETWORKDAYS($C15,TODAY()-1)*$I15,0),0) ) -> 0 | Q15: =IF($A15="","", IF($C15>Q$3+6,0,IF($D15>=Q$3,$I15*5,0) -IF($D15>=Q$3,IF(R$3>$D15,NETWORKDAYS($D15,R$3)-2,0)*$I15,0) -IF(AND($C15>=Q$3,$C15<R$3),($C15-Q$3)*$I15,0)) -IF(AND(TODAY()>=Q$3,TODAY()<R$3),IF(TODAY()>$C15,NETWORKDAYS($C15,TODAY()-1)*$I15,0),0) ) -> 0 | ... U15: =IF($A15="","", IF($C15>U$3+6,0,IF($D15>=U$3,$I15*5,0) -IF($D15>=U$3,IF(V$3>$D15,NETWORKDAYS($D15,V$3)-2,0)*$I15,0) -IF(AND($C15>=U$3,$C15<V$3),($C15-U$3)*$I15,0)) -IF(AND(TODAY()>=U$3,TODAY()<V$3),IF(TODAY()>$C15,NETWORKDAYS($C15,TODAY()-1)*$I15,0),0) ) -> 0 | W15: =SUM(J15:U15) -> -218 | X15: =W15=F15 -> FALSE
A16: Daniela Rojas | B16: Reclutamiento y selección | C16: 45841 | D16: 45847 | E16: 6 | F16: =IF(E16="","",E16-IF(TODAY()<C16,0,(TODAY()-C16)*I16)) -> -386.4 | G16: =IF(E16="","",NETWORKDAYS(TODAY(),D16)+1) -> -229 | H16: =IF(E16="","",G16/5) -> -45.8 | I16: =IF(E16="","",E16/((NETWORKDAYS(C16,D16)))) -> 1.2 | J16: =IF($A16="","", IF($C16>J$3+6,0,IF($D16>=J$3,$I16*5,0) -IF($D16>=J$3,IF(K$3>$D16,NETWORKDAYS($D16,K$3)-2,0)*$I16,0) -IF(AND($C16>=J$3,$C16<K$3),($C16-J$3)*$I16,0)) -IF(AND(TODAY()>=J$3,TODAY()<K$3),IF(TODAY()>$C16,NETWORKDAYS($C16,TODAY()-1)*$I16,0),0) ) -> -279.6 | K16: =IF($A16="","", IF($C16>K$3+6,0,IF($D16>=K$3,$I16*5,0) -IF($D16>=K$3,IF(L$3>$D16,NETWORKDAYS($D16,L$3)-2,0)*$I16,0) -IF(AND($C16>=K$3,$C16<L$3),($C16-K$3)*$I16,0)) -IF(AND(TODAY()>=K$3,TODAY()<L$3),IF(TODAY()>$C16,NETWORKDAYS($C16,TODAY()-1)*$I16,0),0) ) -> 0 | L16: =IF($A16="","", IF($C16>L$3+6,0,IF($D16>=L$3,$I16*5,0) -IF($D16>=L$3,IF(M$3>$D16,NETWORKDAYS($D16,M$3)-2,0)*$I16,0) -IF(AND($C16>=L$3,$C16<M$3),($C16-L$3)*$I16,0)) -IF(AND(TODAY()>=L$3,TODAY()<M$3),IF(TODAY()>$C16,NETWORKDAYS($C16,TODAY()-1)*$I16,0),0) ) -> 0 | M16: =IF($A16="","", IF($C16>M$3+6,0,IF($D16>=M$3,$I16*5,0) -IF($D16>=M$3,IF(N$3>$D16,NETWORKDAYS($D16,N$3)-2,0)*$I16,0) -IF(AND($C16>=M$3,$C16<N$3),($C16-M$3)*$I16,0)) -IF(AND(TODAY()>=M$3,TODAY()<N$3),IF(TODAY()>$C16,NETWORKDAYS($C16,TODAY()-1)*$I16,0),0) ) -> 0 | N16: =IF($A16="","", IF($C16>N$3+6,0,IF($D16>=N$3,$I16*5,0) -IF($D16>=N$3,IF(O$3>$D16,NETWORKDAYS($D16,O$3)-2,0)*$I16,0) -IF(AND($C16>=N$3,$C16<O$3),($C16-N$3)*$I16,0)) -IF(AND(TODAY()>=N$3,TODAY()<O$3),IF(TODAY()>$C16,NETWORKDAYS($C16,TODAY()-1)*$I16,0),0) ) -> 0 | O16: =IF($A16="","", IF($C16>O$3+6,0,IF($D16>=O$3,$I16*5,0) -IF($D16>=O$3,IF(P$3>$D16,NETWORKDAYS($D16,P$3)-2,0)*$I16,0) -IF(AND($C16>=O$3,$C16<P$3),($C16-O$3)*$I16,0)) -IF(AND(TODAY()>=O$3,TODAY()<P$3),IF(TODAY()>$C16,NETWORKDAYS($C16,TODAY()-1)*$I16,0),0) ) -> 0 | P16: =IF($A16="","", IF($C16>P$3+6,0,IF($D16>=P$3,$I16*5,0) -IF($D16>=P$3,IF(Q$3>$D16,NETWORKDAYS($D16,Q$3)-2,0)*$I16,0) -IF(AND($C16>=P$3,$C16<Q$3),($C16-P$3)*$I16,0)) -IF(AND(TODAY()>=P$3,TODAY()<Q$3),IF(TODAY()>$C16,NETWORKDAYS($C16,TODAY()-1)*$I16,0),0) ) -> 0 | Q16: =IF($A16="","", IF($C16>Q$3+6,0,IF($D16>=Q$3,$I16*5,0) -IF($D16>=Q$3,IF(R$3>$D16,NETWORKDAYS($D16,R$3)-2,0)*$I16,0) -IF(AND($C16>=Q$3,$C16<R$3),($C16-Q$3)*$I16,0)) -IF(AND(TODAY()>=Q$3,TODAY()<R$3),IF(TODAY()>$C16,NETWORKDAYS($C16,TODAY()-1)*$I16,0),0) ) -> 0 | ... U16: =IF($A16="","", IF($C16>U$3+6,0,IF($D16>=U$3,$I16*5,0) -IF($D16>=U$3,IF(V$3>$D16,NETWORKDAYS($D16,V$3)-2,0)*$I16,0) -IF(AND($C16>=U$3,$C16<V$3),($C16-U$3)*$I16,0)) -IF(AND(TODAY()>=U$3,TODAY()<V$3),IF(TODAY()>$C16,NETWORKDAYS($C16,TODAY()-1)*$I16,0),0) ) -> 0 | W16: =SUM(J16:U16) -> -279.6 | X16: =W16=F16 -> FALSE
A17: Daniela Rojas | B17: Gestión de conflictos y relaciones laborales | C17: 45841 | D17: 45852 | E17: 4 | F17: =IF(E17="","",E17-IF(TODAY()<C17,0,(TODAY()-C17)*I17)) -> -159.5 | G17: =IF(E17="","",NETWORKDAYS(TODAY(),D17)+1) -> -226 | H17: =IF(E17="","",G17/5) -> -45.2 | I17: =IF(E17="","",E17/((NETWORKDAYS(C17,D17)))) -> 0.5 | J17: =IF($A17="","", IF($C17>J$3+6,0,IF($D17>=J$3,$I17*5,0) -IF($D17>=J$3,IF(K$3>$D17,NETWORKDAYS($D17,K$3)-2,0)*$I17,0) -IF(AND($C17>=J$3,$C17<K$3),($C17-J$3)*$I17,0)) -IF(AND(TODAY()>=J$3,TODAY()<K$3),IF(TODAY()>$C17,NETWORKDAYS($C17,TODAY()-1)*$I17,0),0) ) -> -116.5 | K17: =IF($A17="","", IF($C17>K$3+6,0,IF($D17>=K$3,$I17*5,0) -IF($D17>=K$3,IF(L$3>$D17,NETWORKDAYS($D17,L$3)-2,0)*$I17,0) -IF(AND($C17>=K$3,$C17<L$3),($C17-K$3)*$I17,0)) -IF(AND(TODAY()>=K$3,TODAY()<L$3),IF(TODAY()>$C17,NETWORKDAYS($C17,TODAY()-1)*$I17,0),0) ) -> 0 | L17: =IF($A17="","", IF($C17>L$3+6,0,IF($D17>=L$3,$I17*5,0) -IF($D17>=L$3,IF(M$3>$D17,NETWORKDAYS($D17,M$3)-2,0)*$I17,0) -IF(AND($C17>=L$3,$C17<M$3),($C17-L$3)*$I17,0)) -IF(AND(TODAY()>=L$3,TODAY()<M$3),IF(TODAY()>$C17,NETWORKDAYS($C17,TODAY()-1)*$I17,0),0) ) -> 0 | M17: =IF($A17="","", IF($C17>M$3+6,0,IF($D17>=M$3,$I17*5,0) -IF($D17>=M$3,IF(N$3>$D17,NETWORKDAYS($D17,N$3)-2,0)*$I17,0) -IF(AND($C17>=M$3,$C17<N$3),($C17-M$3)*$I17,0)) -IF(AND(TODAY()>=M$3,TODAY()<N$3),IF(TODAY()>$C17,NETWORKDAYS($C17,TODAY()-1)*$I17,0),0) ) -> 0 | N17: =IF($A17="","", IF($C17>N$3+6,0,IF($D17>=N$3,$I17*5,0) -IF($D17>=N$3,IF(O$3>$D17,NETWORKDAYS($D17,O$3)-2,0)*$I17,0) -IF(AND($C17>=N$3,$C17<O$3),($C17-N$3)*$I17,0)) -IF(AND(TODAY()>=N$3,TODAY()<O$3),IF(TODAY()>$C17,NETWORKDAYS($C17,TODAY()-1)*$I17,0),0) ) -> 0 | O17: =IF($A17="","", IF($C17>O$3+6,0,IF($D17>=O$3,$I17*5,0) -IF($D17>=O$3,IF(P$3>$D17,NETWORKDAYS($D17,P$3)-2,0)*$I17,0) -IF(AND($C17>=O$3,$C17<P$3),($C17-O$3)*$I17,0)) -IF(AND(TODAY()>=O$3,TODAY()<P$3),IF(TODAY()>$C17,NETWORKDAYS($C17,TODAY()-1)*$I17,0),0) ) -> 0 | P17: =IF($A17="","", IF($C17>P$3+6,0,IF($D17>=P$3,$I17*5,0) -IF($D17>=P$3,IF(Q$3>$D17,NETWORKDAYS($D17,Q$3)-2,0)*$I17,0) -IF(AND($C17>=P$3,$C17<Q$3),($C17-P$3)*$I17,0)) -IF(AND(TODAY()>=P$3,TODAY()<Q$3),IF(TODAY()>$C17,NETWORKDAYS($C17,TODAY()-1)*$I17,0),0) ) -> 0 | Q17: =IF($A17="","", IF($C17>Q$3+6,0,IF($D17>=Q$3,$I17*5,0) -IF($D17>=Q$3,IF(R$3>$D17,NETWORKDAYS($D17,R$3)-2,0)*$I17,0) -IF(AND($C17>=Q$3,$C17<R$3),($C17-Q$3)*$I17,0)) -IF(AND(TODAY()>=Q$3,TODAY()<R$3),IF(TODAY()>$C17,NETWORKDAYS($C17,TODAY()-1)*$I17,0),0) ) -> 0 | ... U17: =IF($A17="","", IF($C17>U$3+6,0,IF($D17>=U$3,$I17*5,0) -IF($D17>=U$3,IF(V$3>$D17,NETWORKDAYS($D17,V$3)-2,0)*$I17,0) -IF(AND($C17>=U$3,$C17<V$3),($C17-U$3)*$I17,0)) -IF(AND(TODAY()>=U$3,TODAY()<V$3),IF(TODAY()>$C17,NETWORKDAYS($C17,TODAY()-1)*$I17,0),0) ) -> 0 | W17: =SUM(J17:U17) -> -116.5 | X17: =W17=F17 -> FALSE
... A86: Vicente Castro | B86: Evaluación del desempeño | C86: 45848 | D86: 45855 | E86: 10 | F86: =IF(E86="","",E86-IF(TODAY()<C86,0,(TODAY()-C86)*I86)) -> -523.33333 | G86: =IF(E86="","",NETWORKDAYS(TODAY(),D86)+1) -> -223 | H86: =IF(E86="","",G86/5) -> -44.6 | I86: =IF(E86="","",E86/((NETWORKDAYS(C86,D86)))) -> 1.6666667 | J86: =IF($A86="","", IF($C86>J$3+6,0,IF($D86>=J$3,$I86*5,0) -IF($D86>=J$3,IF(K$3>$D86,NETWORKDAYS($D86,K$3)-2,0)*$I86,0) -IF(AND($C86>=J$3,$C86<K$3),($C86-J$3)*$I86,0)) -IF(AND(TODAY()>=J$3,TODAY()<K$3),IF(TODAY()>$C86,NETWORKDAYS($C86,TODAY()-1)*$I86,0),0) ) -> -380 | K86: =IF($A86="","", IF($C86>K$3+6,0,IF($D86>=K$3,$I86*5,0) -IF($D86>=K$3,IF(L$3>$D86,NETWORKDAYS($D86,L$3)-2,0)*$I86,0) -IF(AND($C86>=K$3,$C86<L$3),($C86-K$3)*$I86,0)) -IF(AND(TODAY()>=K$3,TODAY()<L$3),IF(TODAY()>$C86,NETWORKDAYS($C86,TODAY()-1)*$I86,0),0) ) -> 0 | L86: =IF($A86="","", IF($C86>L$3+6,0,IF($D86>=L$3,$I86*5,0) -IF($D86>=L$3,IF(M$3>$D86,NETWORKDAYS($D86,M$3)-2,0)*$I86,0) -IF(AND($C86>=L$3,$C86<M$3),($C86-L$3)*$I86,0)) -IF(AND(TODAY()>=L$3,TODAY()<M$3),IF(TODAY()>$C86,NETWORKDAYS($C86,TODAY()-1)*$I86,0),0) ) -> 0 | M86: =IF($A86="","", IF($C86>M$3+6,0,IF($D86>=M$3,$I86*5,0) -IF($D86>=M$3,IF(N$3>$D86,NETWORKDAYS($D86,N$3)-2,0)*$I86,0) -IF(AND($C86>=M$3,$C86<N$3),($C86-M$3)*$I86,0)) -IF(AND(TODAY()>=M$3,TODAY()<N$3),IF(TODAY()>$C86,NETWORKDAYS($C86,TODAY()-1)*$I86,0),0) ) -> 0 | N86: =IF($A86="","", IF($C86>N$3+6,0,IF($D86>=N$3,$I86*5,0) -IF($D86>=N$3,IF(O$3>$D86,NETWORKDAYS($D86,O$3)-2,0)*$I86,0) -IF(AND($C86>=N$3,$C86<O$3),($C86-N$3)*$I86,0)) -IF(AND(TODAY()>=N$3,TODAY()<O$3),IF(TODAY()>$C86,NETWORKDAYS($C86,TODAY()-1)*$I86,0),0) ) -> 0 | O86: =IF($A86="","", IF($C86>O$3+6,0,IF($D86>=O$3,$I86*5,0) -IF($D86>=O$3,IF(P$3>$D86,NETWORKDAYS($D86,P$3)-2,0)*$I86,0) -IF(AND($C86>=O$3,$C86<P$3),($C86-O$3)*$I86,0)) -IF(AND(TODAY()>=O$3,TODAY()<P$3),IF(TODAY()>$C86,NETWORKDAYS($C86,TODAY()-1)*$I86,0),0) ) -> 0 | P86: =IF($A86="","", IF($C86>P$3+6,0,IF($D86>=P$3,$I86*5,0) -IF($D86>=P$3,IF(Q$3>$D86,NETWORKDAYS($D86,Q$3)-2,0)*$I86,0) -IF(AND($C86>=P$3,$C86<Q$3),($C86-P$3)*$I86,0)) -IF(AND(TODAY()>=P$3,TODAY()<Q$3),IF(TODAY()>$C86,NETWORKDAYS($C86,TODAY()-1)*$I86,0),0) ) -> 0 | Q86: =IF($A86="","", IF($C86>Q$3+6,0,IF($D86>=Q$3,$I86*5,0) -IF($D86>=Q$3,IF(R$3>$D86,NETWORKDAYS($D86,R$3)-2,0)*$I86,0) -IF(AND($C86>=Q$3,$C86<R$3),($C86-Q$3)*$I86,0)) -IF(AND(TODAY()>=Q$3,TODAY()<R$3),IF(TODAY()>$C86,NETWORKDAYS($C86,TODAY()-1)*$I86,0),0) ) -> 0 | ... U86: =IF($A86="","", IF($C86>U$3+6,0,IF($D86>=U$3,$I86*5,0) -IF($D86>=U$3,IF(V$3>$D86,NETWORKDAYS($D86,V$3)-2,0)*$I86,0) -IF(AND($C86>=U$3,$C86<V$3),($C86-U$3)*$I86,0)) -IF(AND(TODAY()>=U$3,TODAY()<V$3),IF(TODAY()>$C86,NETWORKDAYS($C86,TODAY()-1)*$I86,0),0) ) -> 0 | W86: =SUM(J86:U86) -> -380 | X86: =W86=F86 -> FALSE
A87: Vicente Castro | B87: Administración de personal | C87: 45862 | D87: 45869 | E87: 3 | F87: =IF(E87="","",E87-IF(TODAY()<C87,0,(TODAY()-C87)*I87)) -> -150 | G87: =IF(E87="","",NETWORKDAYS(TODAY(),D87)+1) -> -213 | H87: =IF(E87="","",G87/5) -> -42.6 | I87: =IF(E87="","",E87/((NETWORKDAYS(C87,D87)))) -> 0.5 | J87: =IF($A87="","", IF($C87>J$3+6,0,IF($D87>=J$3,$I87*5,0) -IF($D87>=J$3,IF(K$3>$D87,NETWORKDAYS($D87,K$3)-2,0)*$I87,0) -IF(AND($C87>=J$3,$C87<K$3),($C87-J$3)*$I87,0)) -IF(AND(TODAY()>=J$3,TODAY()<K$3),IF(TODAY()>$C87,NETWORKDAYS($C87,TODAY()-1)*$I87,0),0) ) -> -109 | K87: =IF($A87="","", IF($C87>K$3+6,0,IF($D87>=K$3,$I87*5,0) -IF($D87>=K$3,IF(L$3>$D87,NETWORKDAYS($D87,L$3)-2,0)*$I87,0) -IF(AND($C87>=K$3,$C87<L$3),($C87-K$3)*$I87,0)) -IF(AND(TODAY()>=K$3,TODAY()<L$3),IF(TODAY()>$C87,NETWORKDAYS($C87,TODAY()-1)*$I87,0),0) ) -> 0 | L87: =IF($A87="","", IF($C87>L$3+6,0,IF($D87>=L$3,$I87*5,0) -IF($D87>=L$3,IF(M$3>$D87,NETWORKDAYS($D87,M$3)-2,0)*$I87,0) -IF(AND($C87>=L$3,$C87<M$3),($C87-L$3)*$I87,0)) -IF(AND(TODAY()>=L$3,TODAY()<M$3),IF(TODAY()>$C87,NETWORKDAYS($C87,TODAY()-1)*$I87,0),0) ) -> 0 | M87: =IF($A87="","", IF($C87>M$3+6,0,IF($D87>=M$3,$I87*5,0) -IF($D87>=M$3,IF(N$3>$D87,NETWORKDAYS($D87,N$3)-2,0)*$I87,0) -IF(AND($C87>=M$3,$C87<N$3),($C87-M$3)*$I87,0)) -IF(AND(TODAY()>=M$3,TODAY()<N$3),IF(TODAY()>$C87,NETWORKDAYS($C87,TODAY()-1)*$I87,0),0) ) -> 0 | N87: =IF($A87="","", IF($C87>N$3+6,0,IF($D87>=N$3,$I87*5,0) -IF($D87>=N$3,IF(O$3>$D87,NETWORKDAYS($D87,O$3)-2,0)*$I87,0) -IF(AND($C87>=N$3,$C87<O$3),($C87-N$3)*$I87,0)) -IF(AND(TODAY()>=N$3,TODAY()<O$3),IF(TODAY()>$C87,NETWORKDAYS($C87,TODAY()-1)*$I87,0),0) ) -> 0 | O87: =IF($A87="","", IF($C87>O$3+6,0,IF($D87>=O$3,$I87*5,0) -IF($D87>=O$3,IF(P$3>$D87,NETWORKDAYS($D87,P$3)-2,0)*$I87,0) -IF(AND($C87>=O$3,$C87<P$3),($C87-O$3)*$I87,0)) -IF(AND(TODAY()>=O$3,TODAY()<P$3),IF(TODAY()>$C87,NETWORKDAYS($C87,TODAY()-1)*$I87,0),0) ) -> 0 | P87: =IF($A87="","", IF($C87>P$3+6,0,IF($D87>=P$3,$I87*5,0) -IF($D87>=P$3,IF(Q$3>$D87,NETWORKDAYS($D87,Q$3)-2,0)*$I87,0) -IF(AND($C87>=P$3,$C87<Q$3),($C87-P$3)*$I87,0)) -IF(AND(TODAY()>=P$3,TODAY()<Q$3),IF(TODAY()>$C87,NETWORKDAYS($C87,TODAY()-1)*$I87,0),0) ) -> 0 | Q87: =IF($A87="","", IF($C87>Q$3+6,0,IF($D87>=Q$3,$I87*5,0) -IF($D87>=Q$3,IF(R$3>$D87,NETWORKDAYS($D87,R$3)-2,0)*$I87,0) -IF(AND($C87>=Q$3,$C87<R$3),($C87-Q$3)*$I87,0)) -IF(AND(TODAY()>=Q$3,TODAY()<R$3),IF(TODAY()>$C87,NETWORKDAYS($C87,TODAY()-1)*$I87,0),0) ) -> 0 | ... U87: =IF($A87="","", IF($C87>U$3+6,0,IF($D87>=U$3,$I87*5,0) -IF($D87>=U$3,IF(V$3>$D87,NETWORKDAYS($D87,V$3)-2,0)*$I87,0) -IF(AND($C87>=U$3,$C87<V$3),($C87-U$3)*$I87,0)) -IF(AND(TODAY()>=U$3,TODAY()<V$3),IF(TODAY()>$C87,NETWORKDAYS($C87,TODAY()-1)*$I87,0),0) ) -> 0
F88: =IF(E88="","",E88-IF(TODAY()<C88,0,(TODAY()-C88)*I88)) | G88: =IF(E88="","",NETWORKDAYS(TODAY(),D88)+1) | H88: =IF(E88="","",G88/5) | I88: =IF(E88="","",E88/((NETWORKDAYS(C88,D88)))) | J88: =IF($A88="","", IF($C88>J$3+6,0,IF($D88>=J$3,$I88*5,0) -IF($D88>=J$3,IF(K$3>$D88,NETWORKDAYS($D88,K$3)-2,0)*$I88,0) -IF(AND($C88>=J$3,$C88<K$3),($C88-J$3)*$I88,0)) -IF(AND(TODAY()>=J$3,TODAY()<K$3),IF(TODAY()>$C88,NETWORKDAYS($C88,TODAY()-1)*$I88,0),0) ) | K88: =IF($A88="","", IF($C88>K$3+6,0,IF($D88>=K$3,$I88*5,0) -IF($D88>=K$3,IF(L$3>$D88,NETWORKDAYS($D88,L$3)-2,0)*$I88,0) -IF(AND($C88>=K$3,$C88<L$3),($C88-K$3)*$I88,0)) -IF(AND(TODAY()>=K$3,TODAY()<L$3),IF(TODAY()>$C88,NETWORKDAYS($C88,TODAY()-1)*$I88,0),0) ) | L88: =IF($A88="","", IF($C88>L$3+6,0,IF($D88>=L$3,$I88*5,0) -IF($D88>=L$3,IF(M$3>$D88,NETWORKDAYS($D88,M$3)-2,0)*$I88,0) -IF(AND($C88>=L$3,$C88<M$3),($C88-L$3)*$I88,0)) -IF(AND(TODAY()>=L$3,TODAY()<M$3),IF(TODAY()>$C88,NETWORKDAYS($C88,TODAY()-1)*$I88,0),0) ) | M88: =IF($A88="","", IF($C88>M$3+6,0,IF($D88>=M$3,$I88*5,0) -IF($D88>=M$3,IF(N$3>$D88,NETWORKDAYS($D88,N$3)-2,0)*$I88,0) -IF(AND($C88>=M$3,$C88<N$3),($C88-M$3)*$I88,0)) -IF(AND(TODAY()>=M$3,TODAY()<N$3),IF(TODAY()>$C88,NETWORKDAYS($C88,TODAY()-1)*$I88,0),0) ) | N88: =IF($A88="","", IF($C88>N$3+6,0,IF($D88>=N$3,$I88*5,0) -IF($D88>=N$3,IF(O$3>$D88,NETWORKDAYS($D88,O$3)-2,0)*$I88,0) -IF(AND($C88>=N$3,$C88<O$3),($C88-N$3)*$I88,0)) -IF(AND(TODAY()>=N$3,TODAY()<O$3),IF(TODAY()>$C88,NETWORKDAYS($C88,TODAY()-1)*$I88,0),0) ) | O88: =IF($A88="","", IF($C88>O$3+6,0,IF($D88>=O$3,$I88*5,0) -IF($D88>=O$3,IF(P$3>$D88,NETWORKDAYS($D88,P$3)-2,0)*$I88,0) -IF(AND($C88>=O$3,$C88<P$3),($C88-O$3)*$I88,0)) -IF(AND(TODAY()>=O$3,TODAY()<P$3),IF(TODAY()>$C88,NETWORKDAYS($C88,TODAY()-1)*$I88,0),0) ) | P88: =IF($A88="","", IF($C88>P$3+6,0,IF($D88>=P$3,$I88*5,0) -IF($D88>=P$3,IF(Q$3>$D88,NETWORKDAYS($D88,Q$3)-2,0)*$I88,0) -IF(AND($C88>=P$3,$C88<Q$3),($C88-P$3)*$I88,0)) -IF(AND(TODAY()>=P$3,TODAY()<Q$3),IF(TODAY()>$C88,NETWORKDAYS($C88,TODAY()-1)*$I88,0),0) ) | Q88: =IF($A88="","", IF($C88>Q$3+6,0,IF($D88>=Q$3,$I88*5,0) -IF($D88>=Q$3,IF(R$3>$D88,NETWORKDAYS($D88,R$3)-2,0)*$I88,0) -IF(AND($C88>=Q$3,$C88<R$3),($C88-Q$3)*$I88,0)) -IF(AND(TODAY()>=Q$3,TODAY()<R$3),IF(TODAY()>$C88,NETWORKDAYS($C88,TODAY()-1)*$I88,0),0) ) | ... U88: =IF($A88="","", IF($C88>U$3+6,0,IF($D88>=U$3,$I88*5,0) -IF($D88>=U$3,IF(V$3>$D88,NETWORKDAYS($D88,V$3)-2,0)*$I88,0) -IF(AND($C88>=U$3,$C88<V$3),($C88-U$3)*$I88,0)) -IF(AND(TODAY()>=U$3,TODAY()<V$3),IF(TODAY()>$C88,NETWORKDAYS($C88,TODAY()-1)*$I88,0),0) )
